Workbook

Sheet CONCILIADA
A1: ID_COD | B1: Grupo | C1: Descrição | D1: Linha | E1: Gramatura | F1: CX_EMB | G1: DESCRICAONF | H1: PRECO
A2: 1 | B2: COMPRESSA ESTÉRIL | C2: Estéril 9 fios | D2: Med Mais | F2: =VLOOKUP(Tabela14[[#This Row],[ID_COD]],Tabela2[],6,0) -> 1000 | G2: GAZE ESTÉRIL 09 FIOS - PCT 10 UND | H2: =VLOOKUP(A2,'Tabela de preços'!A1:H87,8,FALSE) -> 0.4104
A3: 2 | B3: COMPRESSA ESTÉRIL | C3: Estéril 11 fios | D3: Med Mais | F3: =VLOOKUP(Tabela14[[#This Row],[ID_COD]],Tabela2[],6,0) -> 1000 | G3: GAZE ESTÉRIL 11FIOS - PCT 10 UND | H3: =VLOOKUP(A3,'Tabela de preços'!A2:H88,8,FALSE) -> 0.432
A4: 3 | B4: COMPRESSA ESTÉRIL | C4: Estéril 13 fios | D4: Med Mais | F4: =VLOOKUP(Tabela14[[#This Row],[ID_COD]],Tabela2[],6,0) -> 1000 | G4: GAZE ESTÉRIL 13FIOS - PCT 10 UND | H4: =VLOOKUP(A4,'Tabela de preços'!A3:H89,8,FALSE) -> 0.4536
A5: 152 | B5: COMPRESSA ESTÉRIL | C5: Estéril 9 fios | D5: Ultra Textil | F5: =VLOOKUP(Tabela14[[#This Row],[ID_COD]],Tabela2[],6,0) -> 1000 | G5: GAZE ESTERIL 09 FIOS ULTRA TEXTIL PCT 10 UND | H5: =VLOOKUP(A5,'Tabela de preços'!A4:H90,8,FALSE) -> 0.4752
A6: 153 | B6: COMPRESSA ESTÉRIL | C6: Estéril 11 fios | D6: Ultra Textil | F6: =VLOOKUP(Tabela14[[#This Row],[ID_COD]],Tabela2[],6,0) -> 1000 | G6: GAZE ESTERIL 11 FIOS PCT 10 UND | H6: =VLOOKUP(A6,'Tabela de preços'!A5:H91,8,FALSE) -> 0.5076
A7: 154 | B7: COMPRESSA ESTÉRIL | C7: Estéril 13 fios | D7: Ultra Textil | F7: =VLOOKUP(Tabela14[[#This Row],[ID_COD]],Tabela2[],6,0) -> 1000 | G7: GAZE ESTERIL 13 FIOS PCT 10 UND | H7: =VLOOKUP(A7,'Tabela de preços'!A6:H92,8,FALSE) -> 0.5292
A8: 1641 | B8: COMPRESSA ESTÉRIL | C8: Estéril 9 fios | D8: Med Textil | F8: =VLOOKUP(Tabela14[[#This Row],[ID_COD]],Tabela2[],6,0) -> 0 | G8: GAZE ESTÉRIL 09 FIOS - PCT 10 UND | H8: =VLOOKUP(A8,'Tabela de preços'!A7:H93,8,FALSE) -> 0.648
A9: 1642 | B9: COMPRESSA ESTÉRIL | C9: Estéril 11 fios | D9: Med Textil | F9: =VLOOKUP(Tabela14[[#This Row],[ID_COD]],Tabela2[],6,0) -> 900 | G9: GAZE ESTÉRIL 11FIOS - PCT 10 UND | H9: =VLOOKUP(A9,'Tabela de preços'!A8:H94,8,FALSE) -> 0.6696
A10: 1643 | B10: COMPRESSA ESTÉRIL | C10: Estéril 13 fios | D10: Med Textil | F10: =VLOOKUP(Tabela14[[#This Row],[ID_COD]],Tabela2[],6,0) -> 900 | G10: GAZE ESTÉRIL 13FIOS - PCT 10 UND | H10: =VLOOKUP(A10,'Tabela de preços'!A9:H95,8,FALSE) -> 0.702
A11: 1587 | B11: CAMPOS OPERATÓRIOS | C11: CAMPO C/ 2 | D11: Med Mais | F11: =VLOOKUP(Tabela14[[#This Row],[ID_COD]],Tabela2[],6,0) -> 300 | G11: CAMPO OPERATORIO ESTERIL 25X28 - PCT 2 UND | H11: =VLOOKUP(A11,'Tabela de preços'!A10:H96,8,FALSE) -> 2.884
A12: 1588 | B12: CAMPOS OPERATÓRIOS | C12: CAMPO C/ 5 | D12: Med Mais | F12: =VLOOKUP(Tabela14[[#This Row],[ID_COD]],Tabela2[],6,0) -> 150 | G12: CAMPO OPERATORIO ESTERIL 25X28 - PCT 5 UND | H12: =VLOOKUP(A12,'Tabela de preços'!A11:H97,8,FALSE) -> 5.3354
A13: 1586 | B13: CAMPOS OPERATÓRIOS | C13: CAMPO 45 X 50 | D13: Med Mais | F13: =VLOOKUP(Tabela14[[#This Row],[ID_COD]],Tabela2[],6,0) -> 12 | G13: CAMPO OPERATORIO NAO ESTERIL 45X50 - PCT 50 | H13: 49.5
A14: 157 | B14: CAMPOS OPERATÓRIOS | C14: CAMPO C/ 2 | D14: Ultra Textil | F14: =VLOOKUP(Tabela14[[#This Row],[ID_COD]],Tabela2[],6,0) -> 300 | G14: CAMPO OPERATORIO ESTERIL 25X28 - PCT 2 UND | H14: =VLOOKUP(A14,'Tabela de preços'!A13:H99,8,FALSE) -> #N/A
A15: 158 | B15: CAMPOS OPERATÓRIOS | C15: CAMPO C/ 5 | D15: Ultra Textil | F15: =VLOOKUP(Tabela14[[#This Row],[ID_COD]],Tabela2[],6,0) -> 150 | G15: CAMPO OPERATORIO ESTERIL 25X28 - PCT 5 UND | H15: =VLOOKUP(A15,'Tabela de preços'!A14:H100,8,FALSE) -> 7.1894
A16: 155 | B16: CAMPOS OPERATÓRIOS | C16: CAMPO 45 X 50 | D16: Ultra Textil | F16: =VLOOKUP(Tabela14[[#This Row],[ID_COD]],Tabela2[],6,0) -> 0 | G16: CAMPO OPERATORIO NAO ESTERIL 45X50 - PCT 50 UND | H16: 71
A17: 1639 | B17: CAMPOS OPERATÓRIOS | C17: CAMPO C/ 2 | D17: Med Textil | F17: =VLOOKUP(Tabela14[[#This Row],[ID_COD]],Tabela2[],6,0) -> 0 | G17: CAMPO OPERATORIO ESTERIL 25X28 - PCT 2 UND | H17: =VLOOKUP(A17,'Tabela de preços'!A16:H102,8,FALSE) -> 4.4084
A18: 1640 | B18: CAMPOS OPERATÓRIOS | C18: CAMPO C/ 5 | D18: Med Textil | F18: =VLOOKUP(Tabela14[[#This Row],[ID_COD]],Tabela2[],6,0) -> 150 | G18: CAMPO OPERATORIO ESTERIL 25X28 - PCT 5 UND | H18: 7.96
A19: 1209 | B19: CAMPOS OPERATÓRIOS | C19: CAMPO 45 X 50 | D19: Med Textil | F19: =VLOOKUP(Tabela14[[#This Row],[ID_COD]],Tabela2[],6,0) -> 12 | G19: CAMPO OPERATORIO NAO ESTERIL 45X50 - PCT 50 | H19: 86.5
A20: 5 | B20: COMPRESSA NÃO ESTÉRIL – 9 FIOS | C20: COMPRESSA 9 FIOS | D20: Med Mais | E20: 70 | F20: =VLOOKUP(Tabela14[[#This Row],[ID_COD]],Tabela2[],6,0) -> 0 | G20: GAZE NAO ESTÉRIL 09 FIOS | H20: =(Tabela14[[#This Row],[Gramatura]]*6.99)/105 -> 4.66
A21: 6 | B21: COMPRESSA NÃO ESTÉRIL – 9 FIOS | C21: COMPRESSA 9 FIOS | D21: Med Mais | E21: 80 | F21: =VLOOKUP(Tabela14[[#This Row],[ID_COD]],Tabela2[],6,0) -> 0 | G21: GAZE NAO ESTÉRIL 09 FIOS | H21: =(Tabela14[[#This Row],[Gramatura]]*6.99)/105 -> 5.3257143
A22: 7 | B22: COMPRESSA NÃO ESTÉRIL – 9 FIOS | C22: COMPRESSA 9 FIOS | D22: Med Mais | E22: 90 | F22: =VLOOKUP(Tabela14[[#This Row],[ID_COD]],Tabela2[],6,0) -> 0 | G22: GAZE NAO ESTÉRIL 09 FIOS | H22: =(Tabela14[[#This Row],[Gramatura]]*6.99)/105 -> 5.9914286
A23: 8 | B23: COMPRESSA NÃO ESTÉRIL – 9 FIOS | C23: COMPRESSA 9 FIOS | D23: Med Mais | E23: 105 | F23: =VLOOKUP(Tabela14[[#This Row],[ID_COD]],Tabela2[],6,0) -> 72 | G23: GAZE NAO ESTÉRIL 09 FIOS | H23: 6.99
A24: 9 | B24: COMPRESSA NÃO ESTÉRIL – 9 FIOS | C24: COMPRESSA 9 FIOS | D24: Med Mais | E24: 110 | F24: =VLOOKUP(Tabela14[[#This Row],[ID_COD]],Tabela2[],6,0) -> 0 | G24: GAZE NAO ESTÉRIL 09 FIOS E | H24: 7.3228571
A25: 10 | B25: COMPRESSA NÃO ESTÉRIL – 9 FIOS | C25: COMPRESSA 9 FIOS | D25: Med Mais | E25: 120 | F25: =VLOOKUP(Tabela14[[#This Row],[ID_COD]],Tabela2[],6,0) -> 60 | G25: GAZE NAO ESTÉRIL 09 FIOS F | H25: 7.9885714
A26: 11 | B26: COMPRESSA NÃO ESTÉRIL – 9 FIOS | C26: COMPRESSA 9 FIOS | D26: Med Mais | E26: 130 | F26: =VLOOKUP(Tabela14[[#This Row],[ID_COD]],Tabela2[],6,0) -> 50 | G26: GAZE NAO ESTÉRIL 09 FIOS G | H26: 8.6542857
A27: 12 | B27: COMPRESSA NÃO ESTÉRIL – 9 FIOS | C27: COMPRESSA 9 FIOS | D27: Med Mais | E27: 140 | F27: =VLOOKUP(Tabela14[[#This Row],[ID_COD]],Tabela2[],6,0) -> 0 | G27: GAZE NAO ESTÉRIL 09 FIOS H | H27: 9.32
A28: 13 | B28: COMPRESSA NÃO ESTÉRIL – 9 FIOS | C28: COMPRESSA 9 FIOS | D28: Med Mais | E28: 150 | F28: =VLOOKUP(Tabela14[[#This Row],[ID_COD]],Tabela2[],6,0) -> 50 | G28: GAZE NAO ESTÉRIL 09 FIOS I | H28: 10.88
A29: 14 | B29: COMPRESSA NÃO ESTÉRIL – 9 FIOS | C29: COMPRESSA 9 FIOS | D29: Med Mais | E29: 160 | F29: =VLOOKUP(Tabela14[[#This Row],[ID_COD]],Tabela2[],6,0) -> 0 | G29: GAZE NAO ESTÉRIL 09 FIOS J | H29: 10.651429
A30: 15 | B30: COMPRESSA NÃO ESTÉRIL – 9 FIOS | C30: COMPRESSA 9 FIOS | D30: Med Mais | E30: 170 | F30: =VLOOKUP(Tabela14[[#This Row],[ID_COD]],Tabela2[],6,0) -> 0 | G30: GAZE NAO ESTÉRIL 09 FIOS L | H30: 11.317143
A31: 16 | B31: COMPRESSA NÃO ESTÉRIL – 9 FIOS | C31: COMPRESSA 9 FIOS | D31: Med Mais | E31: 180 | F31: =VLOOKUP(Tabela14[[#This Row],[ID_COD]],Tabela2[],6,0) -> 40 | G31: GAZE NAO ESTÉRIL 09 FIOS M | H31: 11.982857
A32: 17 | B32: COMPRESSA NÃO ESTÉRIL – 9 FIOS | C32: COMPRESSA 9 FIOS | D32: Med Mais | E32: 190 | F32: =VLOOKUP(Tabela14[[#This Row],[ID_COD]],Tabela2[],6,0) -> 0 | G32: GAZE NAO ESTÉRIL 09 FIOS N | H32: 12.648571
A33: 18 | B33: COMPRESSA NÃO ESTÉRIL – 9 FIOS | C33: COMPRESSA 9 FIOS | D33: Med Mais | E33: 200 | F33: =VLOOKUP(Tabela14[[#This Row],[ID_COD]],Tabela2[],6,0) -> 0 | G33: GAZE NAO ESTÉRIL 09 FIOS O | H33: 13.314286
A34: 51 | B34: COMPRESSA NÃO ESTÉRIL – 9 FIOS | C34: COMPRESSA 9 FIOS | D34: Ultra Textil | E34: 210 | F34: =VLOOKUP(Tabela14[[#This Row],[ID_COD]],Tabela2[],6,0) -> 40 | G34: GAZE NAO ESTÉRIL 09 FIOS - PCT 500 UND | H34: 14.46
A35: 52 | B35: COMPRESSA NÃO ESTÉRIL – 9 FIOS | C35: COMPRESSA 9 FIOS | D35: Ultra Textil | E35: 220 | F35: =VLOOKUP(Tabela14[[#This Row],[ID_COD]],Tabela2[],6,0) -> 0 | G35: GAZE NAO ESTÉRIL 09 FIOS B | H35: 15.148571
... A135: 136 | B135: GAZE EM ROLO – 9 FIOS | C135: ROLO 9 FIOS | D135: Ultra Textil | E135: 410 | F135: =VLOOKUP(Tabela14[[#This Row],[ID_COD]],Tabela2[],6,0) -> 0 | G135: GAZE CIRCULAR NAO ESTERIL 09 FIOS H | H135: 32.877568
A136: 1960 | B136: GAZE EM ROLO – 9 FIOS | C136: ROLO 9 FIOS | D136: Med Textil | E136: 1460 | F136: 7 | G136: GAZE CIRCULAR NAO ESTERIL 09 FIOS | H136: 94.88
A137: 1775 | B137: GAZE EM ROLO – 9 FIOS | C137: ROLO 9 FIOS | D137: Med Textil | E137: 400 | F137: =VLOOKUP(Tabela14[[#This Row],[ID_COD]],Tabela2[],6,0) -> 0 | G137: GAZE CIRCULAR NAO ESTERIL 09 FIOS A | H137: 32.075676
A138: 1776 | B138: GAZE EM ROLO – 9 FIOS | C138: ROLO 9 FIOS | D138: Med Textil | E138: 410 | F138: =VLOOKUP(Tabela14[[#This Row],[ID_COD]],Tabela2[],6,0) -> 0 | G138: GAZE CIRCULAR NAO ESTERIL 09 FIOS B | H138: 32.877568
A139: 1777 | B139: GAZE EM ROLO – 9 FIOS | C139: ROLO 9 FIOS | D139: Med Textil | E139: 420 | F139: =VLOOKUP(Tabela14[[#This Row],[ID_COD]],Tabela2[],6,0) -> 0 | G139: GAZE CIRCULAR NAO ESTERIL 09 FIOS C | H139: 33.679459
...

Sheet Tabela de preços
A1: Cod | B1: Produto | C1: Apresentacao | D1: Fios | E1: Unid_Caixa | F1: Linha | G1: Gramat | H1: Preco
A2: 8 | B2: COMPRESSA DE GAZE NÃO ESTERIL | C2: 7,5 X 7,5 - 13x24 (aberta) | D2: 9 fios | E2: 72 | F2: Med Mais | G2: 105gr | H2: 6.99
A3: 310 | B3: COMPRESSA DE GAZE NÃO ESTERIL | C3: 7,5 X 7,5 - 13x24 (aberta) | D3: 11 fios | E3: 60 | F3: Med Mais | G3: 130gr | H3: 9.74
A4: 326 | B4: COMPRESSA DE GAZE NÃO ESTERIL | C4: 7,5 X 7,5 - 13x24 (aberta) | D4: 13 fios | E4: 50 | F4: Med Mais | G4: 150gr | H4: 11.85
A5: 13 | B5: COMPRESSA DE GAZE NÃO ESTERIL | C5: 7,5 X 7,5 - 13x24 (aberta) | D5: 9 fios | E5: 50 | F5: Med Mais | G5: 150gr | H5: 10.88
A6: 313 | B6: COMPRESSA DE GAZE NÃO ESTERIL | C6: 7,5 X 7,5 - 13x24 (aberta) | D6: 11 fios | E6: 50 | F6: Med Mais | G6: 160gr | H6: 11.98
A7: 329 | B7: COMPRESSA DE GAZE NÃO ESTERIL | C7: 7,5 X 7,5 - 13x24 (aberta) | D7: 13 fios | E7: 50 | F7: Med Mais | G7: 180gr | H7: 14.22
A8: 85 | B8: GAZE HIDROFILA CIRCULAR | C8: Tipo Queijo 91 | D8: 9 fios | E8: 36 | F8: Med Mais | G8: 210gr | H8: 15.44
A9: 263 | B9: GAZE HIDROFILA CIRCULAR | C9: Tipo Queijo 91 | D9: 11 fios | E9: 30 | F9: Med Mais | G9: 250gr | H9: 18.86
A10: 279 | B10: GAZE HIDROFILA CIRCULAR | C10: Tipo Queijo 91 | D10: 13 fios | E10: 30 | F10: Med Mais | G10: 270gr | H10: 19.88
A11: 94 | B11: GAZE HIDROFILA CIRCULAR | C11: Tipo Queijo 91 | D11: 9 fios | E11: 30 | F11: Med Mais | G11: 300gr | H11: 22.8
A12: 271 | B12: GAZE HIDROFILA CIRCULAR | C12: Tipo Queijo 91 | D12: 11 fios | E12: 25 | F12: Med Mais | G12: 320gr | H12: 24.86
A13: 286 | B13: GAZE HIDROFILA CIRCULAR | C13: Tipo Queijo 91 | D13: 13 fios | E13: 25 | F13: Med Mais | G13: 340gr | H13: 26.86
A14: 1 | B14: COMPRESSA ESTÉRIL – 9FIOS | C14: 7,5 X 7,5 - 13x24 (aberta) | D14: 9 fios | E14: 1000 | F14: Med Mais | H14: 0.4104
A15: 2 | B15: COMPRESSA ESTÉRIL – 11FIOS | C15: 7,5 X 7,5 - 13x24 (aberta) | D15: 11 fios | E15: 1000 | F15: Med Mais | H15: 0.432
A16: 3 | B16: COMPRESSA ESTÉRIL – 13FIOS | C16: 7,5 X 7,5 - 13x24 (aberta) | D16: 13 fios | E16: 1000 | F16: Med Mais | H16: 0.4536
A17: 1586 | B17: CAMPO OPERATÓRIO 45X50 (Com Radiopaco) | C17: PCT C/50 | E17: 12 | F17: Med Mais | H17: 49.5
A18: 1797 | B18: CAMPO OPERATÓRIO 45X50 (Sem Radiopaco) | C18: PCT C/50 | E18: 12 | F18: Med Mais | H18: 48.5
A19: 1588 | B19: CAMPO OPERATÓRIO – Pré encolhido | C19: PCT C/5 UND | E19: 150 | F19: Med Mais | H19: 5.3354
A20: 1587 | B20: CAMPO OPERATÓRIO – Pré encolhido | C20: PCT C/2 UND | E20: 300 | F20: Med Mais | H20: 2.884
A21: 1644 | B21: ATADURA DE CREPE - FARMA | C21: 08CM x 1,20M | D21: 13 FIOS | E21: 115 DUZIAS | F21: Med Mais | H21: 3.9528
A22: 1589 | B22: ATADURA DE CREPE - FARMA | C22: 10CM x 1,20M | D22: 13 FIOS | E22: 110 DUZIAS | F22: Med Mais | H22: 4.2876
A23: 1590 | B23: ATADURA DE CREPE - FARMA | C23: 12CM x 1,20M | D23: 13 FIOS | E23: 110 DUZIAS | F23: Med Mais | H23: 5.3028
A24: 1592 | B24: ATADURA DE CREPE - FARMA | C24: 15CM x 1,20M | D24: 13 FIOS | E24: 90 DUZIAS | F24: Med Mais | H24: 6.0804
A25: 1593 | B25: ATADURA DE CREPE - FARMA | C25: 20CM x 1,20M | D25: 13 FIOS | E25: 70 DUZIAS | F25: Med Mais | H25: 7.83
A26: 1594 | B26: ATADURA DE CREPE - FARMA | C26: 30CM x 1,20M | D26: 13 FIOS | E26: 50 DUZIAS | F26: Med Mais | H26: 11.5992
A27: 1973 | B27: ATADURA DE CREPE - FARMA | C27: 08CM x 1,80M | D27: 13 FIOS | E27: 105 DUZIAS | F27: Med Mais | H27: 5.3568
A28: 1595 | B28: ATADURA DE CREPE - FARMA | C28: 10CM x 1,80M | D28: 13 FIOS | E28: 100 DUZIAS | F28: Med Mais | H28: 5.8104
A29: 1596 | B29: ATADURA DE CREPE - FARMA | C29: 12CM x 1,80M | D29: 13 FIOS | E29: 90 DUZIAS | F29: Med Mais | H29: 7.3224
A30: 1597 | B30: ATADURA DE CREPE - FARMA | C30: 15CM x 1,80M | D30: 13 FIOS | E30: 75 DUZIAS | F30: Med Mais | H30: 8.5752
A31: 1598 | B31: ATADURA DE CREPE - FARMA | C31: 20CM x 1,80M | D31: 13 FIOS | E31: 60 DUZIAS | F31: Med Mais | H31: 11.124
A32: 1599 | B32: ATADURA DE CREPE - FARMA | C32: 30CM x 1,80M | D32: 13 FIOS | E32: 40 DUZIAS | F32: Med Mais | H32: 15.9192
... A42: 1615 | B42: ATADURA DE CREPE - HOSPITALAR | C42: 30CM x 1,80M | D42: 13 FIOS | E42: 28 DUZIAS | F42: Med Mais | H42: 15.444
A43: 51 | B43: COMPRESSA DE GAZE NÃO ESTERIL | C43: 7,5 X 7,5 - 15x26 (aberta) | D43: 9 fios | E43: 40 | F43: Ultra Têxtil | G43: 500 und | H43: 14.46
A44: 339 | B44: COMPRESSA DE GAZE NÃO ESTERIL | C44: 7,5 X 7,5 - 15x26 (aberta) | D44: 11 fios | E44: 32 | F44: Ultra Têxtil | G44: 500 und | H44: 16.58
A45: 349 | B45: COMPRESSA DE GAZE NÃO ESTERIL | C45: 7,5 X 7,5 - 15x26 (aberta) | D45: 13 fios | E45: 32 | F45: Ultra Têxtil | G45: 500 und | H45: 19.22
A46: 132 | B46: GAZE HIDROFILA CIRCULAR | C46: Tipo Queijo 91 | D46: 9 fios | E46: 20 | F46: Ultra Têxtil | G46: 370gr | H46: 29.67
A47: 294 | B47: GAZE HIDROFILA CIRCULAR | C47: Tipo Queijo 91 | D47: 11 fios | E47: 20 | F47: Ultra Têxtil | G47: 380gr | H47: 30.58
A48: 300 | B48: GAZE HIDROFILA CIRCULAR | C48: Tipo Queijo 91 | D48: 13 fios | E48: 20 | F48: Ultra Têxtil | G48: 410gr | H48: 32.94
A49: 152 | B49: COMPRESSA ESTÉRIL – 9FIOS | C49: 7,5 X 7,5 - 15x26 (aberta) | D49: 9 fios | E49: 1000 | F49: Ultra Têxtil | H49: 0.4752
...

Sheet Estoque
A1: COD | B1: DESCRIÇÃO | C1: PESO | D1: TIPO | E1: VOL. | F1: UNID. | G1: TOTAL
A2: 1 | B2: COMPRESSA ESTÉRIL Estéril 9 fios | D2: Med Mais | E2: 0 | F2: 1000 | G2: #VALUE!
A3: 2 | B3: COMPRESSA ESTÉRIL Estéril 11 fios | D3: Med Mais | E3: 14 | F3: 1000 | G3: #VALUE!
A4: 3 | B4: COMPRESSA ESTÉRIL Estéril 13 fios | D4: Med Mais | E4: 0 | F4: 1000 | G4: 14000
A5: 4 | B5: COMPRESSA ESTÉRIL ESTÉRIL 13 FIOS CONVIVA | D5: Conviva (Marca Própria) | E5: 13 | F5: 1000 | G5: 0
A6: 1 | B6: COMPRESSA ESTÉRIL Estéril 9 fios | D6: Med Mais | E6: 0 | F6: 1000 | G6: 0
A7: 2 | B7: COMPRESSA ESTÉRIL Estéril 11 fios | D7: Med Mais | E7: 0 | F7: 1000 | G7: 0
A8: 3 | B8: COMPRESSA ESTÉRIL Estéril 13 fios | D8: Med Mais | E8: 0 | F8: 1000 | G8: 0
A9: 152 | B9: COMPRESSA ESTÉRIL Estéril 9 fios | D9: Ultra Textil | E9: 9 | F9: 1000 | G9: 0
A10: 153 | B10: COMPRESSA ESTÉRIL Estéril 11 fios | D10: Ultra Textil | E10: 0 | F10: 1000 | G10: 0
A11: 154 | B11: COMPRESSA ESTÉRIL Estéril 13 fios | D11: Ultra Textil | E11: 0 | F11: 1000 | G11: 288
A12: 1641 | B12: COMPRESSA ESTÉRIL Estéril 9 fios | D12: Med Textil | E12: 0 | G12: 0
A13: 1642 | B13: COMPRESSA ESTÉRIL Estéril 11 fios | D13: Med Textil | E13: 0 | F13: 900 | G13: 60
A14: 1643 | B14: COMPRESSA ESTÉRIL Estéril 13 fios | D14: Med Textil | E14: 14 | F14: 900 | G14: 0
A15: 1587 | B15: CAMPOS OPERATÓRIOS CAMPO C/ 2 | D15: Med Mais | E15: 0 | F15: 300 | G15: 0
A16: 1588 | B16: CAMPOS OPERATÓRIOS CAMPO C/ 5 | D16: Med Mais | E16: 0 | F16: 150 | G16: 0
A17: 1586 | B17: CAMPOS OPERATÓRIOS CAMPO 45 X 50 | D17: Med Mais | E17: 1 | F17: 12 | G17: 0
A18: 157 | B18: CAMPOS OPERATÓRIOS CAMPO C/ 2 | D18: Ultra Textil | E18: 0 | F18: 300 | G18: 0
A19: 158 | B19: CAMPOS OPERATÓRIOS CAMPO C/ 5 | D19: Ultra Textil | E19: 0 | F19: 150 | G19: 0
A20: 155 | B20: CAMPOS OPERATÓRIOS CAMPO 45 X 50 | D20: Ultra Textil | E20: 0 | G20: 0
A21: 1639 | B21: CAMPOS OPERATÓRIOS CAMPO C/ 2 | D21: Med Textil | E21: 0 | G21: 0
A22: 1640 | B22: CAMPOS OPERATÓRIOS CAMPO C/ 5 | D22: Med Textil | E22: 0 | F22: 150 | G22: 0
A23: 1209 | B23: CAMPOS OPERATÓRIOS CAMPO 45 X 50 | D23: Med Textil | E23: 0 | F23: 12 | G23: 200
A24: 5 | B24: COMPRESSA NÃO ESTÉRIL – 9 FIOS COMPRESSA 9 FIOS | C24: 70 | D24: Med Mais | E24: 0 | G24: 0
A25: 6 | B25: COMPRESSA NÃO ESTÉRIL – 9 FIOS COMPRESSA 9 FIOS | C25: 80 | D25: Med Mais | E25: 4 | G25: 0
A26: 7 | B26: COMPRESSA NÃO ESTÉRIL – 9 FIOS COMPRESSA 9 FIOS | C26: 90 | D26: Med Mais | E26: 0 | G26: 0
A27: 8 | B27: COMPRESSA NÃO ESTÉRIL – 9 FIOS COMPRESSA 9 FIOS | C27: 100 | D27: Med Mais | E27: 0 | F27: 72 | G27: 90
A28: 9 | B28: COMPRESSA NÃO ESTÉRIL – 9 FIOS COMPRESSA 9 FIOS | C28: 110 | D28: Med Mais | E28: 0 | G28: 0
A29: 10 | B29: COMPRESSA NÃO ESTÉRIL – 9 FIOS COMPRESSA 9 FIOS | C29: 120 | D29: Med Mais | E29: 3 | F29: 60 | G29: 0
A30: 11 | B30: COMPRESSA NÃO ESTÉRIL – 9 FIOS COMPRESSA 9 FIOS | C30: 130 | D30: Med Mais | E30: 0 | F30: 50 | G30: 0
A31: 12 | B31: COMPRESSA NÃO ESTÉRIL – 9 FIOS COMPRESSA 9 FIOS | C31: 140 | D31: Med Mais | E31: 0 | G31: 96
A32: 13 | B32: COMPRESSA NÃO ESTÉRIL – 9 FIOS COMPRESSA 9 FIOS | C32: 150 | D32: Med Mais | E32: 0 | F32: 50 | G32: 0
A33: 14 | B33: COMPRESSA NÃO ESTÉRIL – 9 FIOS COMPRESSA 9 FIOS | C33: 160 | D33: Med Mais | E33: 4 | G33: 0
A34: 15 | B34: COMPRESSA NÃO ESTÉRIL – 9 FIOS COMPRESSA 9 FIOS | C34: 170 | D34: Med Mais | E34: 0 | G34: 0
A35: 16 | B35: COMPRESSA NÃO ESTÉRIL – 9 FIOS COMPRESSA 9 FIOS | C35: 180 | D35: Med Mais | E35: 4 | F35: 40 | G35: 192
A36: 17 | B36: COMPRESSA NÃO ESTÉRIL – 9 FIOS COMPRESSA 9 FIOS | C36: 190 | D36: Med Mais | E36: 0 | G36: 0
A37: 18 | B37: COMPRESSA NÃO ESTÉRIL – 9 FIOS COMPRESSA 9 FIOS | C37: 200 | D37: Med Mais | E37: 0 | G37: 128
A38: 51 | B38: COMPRESSA NÃO ESTÉRIL – 9 FIOS COMPRESSA 9 FIOS | C38: 210 | D38: Ultra Textil | E38: 0 | F38: 40 | G38: 0
A39: 52 | B39: COMPRESSA NÃO ESTÉRIL – 9 FIOS COMPRESSA 9 FIOS | C39: 220 | D39: Ultra Textil | E39: 0 | G39: 0
A40: 53 | B40: COMPRESSA NÃO ESTÉRIL – 9 FIOS COMPRESSA 9 FIOS | C40: 230 | D40: Ultra Textil | E40: 0 | G40: 0
...
