Workbook

Sheet TAB 3%
A1: TABELA DE PREÇOS
A5: COMPRESSAS DE GAZES – PACOTE
A6: CÓD. | B6: PRODUTO | C6: APRESENTAÇÃO | E6: UND CAIXA | F6: LINHA | G6: MARCA | H6: GRAMAT | I6: PREÇO
A8: 8 | B8: COMPRESSA DE GAZE NÃO ESTERIL | C8: PACOTE 105gr | D8: 9 fios | E8: 72 | F8: COMBATE | G8: Med Mais | H8: 105gr | I8: =(J8*$J$6)+J8 -> 6.99 | J8: 6.99
A9: 310 | B9: COMPRESSA DE GAZE NÃO ESTERIL | C9: PACOTE 130gr | D9: 11 fios | E9: 60 | F9: COMBATE | G9: Med Mais | H9: 130gr | I9: =(J9*$J$6)+J9 -> 9.74 | J9: 9.74
A10: 326 | B10: COMPRESSA DE GAZE NÃO ESTERIL | C10: PACOTE 150gr | D10: 13 fios | E10: 50 | F10: COMBATE | G10: Med Mais | H10: 150gr | I10: =(J10*$J$6)+J10 -> 11.85 | J10: 11.85
A11: 13 | B11: COMPRESSA DE GAZE NÃO ESTERIL | C11: PACOTE 150gr | D11: 9 fios | E11: 50 | F11: INTERMEDIARIA | G11: Med Mais | H11: 150gr | I11: =(J11*$J$6)+J11 -> 10.88 | J11: 10.88
A12: 313 | B12: COMPRESSA DE GAZE NÃO ESTERIL | C12: PACOTE 160gr | D12: 11 fios | E12: 50 | F12: INTERMEDIARIA | G12: Med Mais | H12: 160gr | I12: =(J12*$J$6)+J12 -> 11.98 | J12: 11.98
A13: 329 | B13: COMPRESSA DE GAZE NÃO ESTERIL | C13: PACOTE 180gr | D13: 13 fios | E13: 50 | F13: INTERMEDIARIA | G13: Med Mais | H13: 180gr | I13: =(J13*$J$6)+J13 -> 14.22 | J13: 14.22
A14: 51 | B14: COMPRESSA DE GAZE NÃO ESTERIL | C14: 7,5 X 7,5 - 15x26 (aberta) | D14: 9 fios | E14: 40 | F14: EXTRA | G14: Ultra Têxtil | H14: 500 und | I14: =(J14*$J$6)+J14 -> 14.46 | J14: 14.46
A15: 339 | B15: COMPRESSA DE GAZE NÃO ESTERIL | C15: 7,5 X 7,5 - 15x26 (aberta) | D15: 11 fios | E15: 32 | F15: EXTRA | G15: Ultra Têxtil | H15: 500 und | I15: =(J15*$J$6)+J15 -> 16.58 | J15: 16.58
A16: 349 | B16: COMPRESSA DE GAZE NÃO ESTERIL | C16: 7,5 X 7,5 - 15x26 (aberta) | D16: 13 fios | E16: 32 | F16: EXTRA | G16: Ultra Têxtil | H16: 500 und | I16: =(J16*$J$6)+J16 -> 19.22 | J16: 19.22
A17: 1957 | B17: COMPRESSA DE GAZE NÃO ESTERIL | C17: 7,5 X 7,5 - 15x30 (aberta) | D17: 9 fios | E17: 40 | F17: EXTRA | G17: Medtextil | H17: 500 und | I17: =(J17*$J$6)+J17 -> 27.88 | J17: 27.88
A18: 1958 | B18: COMPRESSA DE GAZE NÃO ESTERIL | C18: 7,5 X 7,5 - 15x30 (aberta) | D18: 11 fios | E18: 32 | F18: EXTRA | G18: Medtextil | H18: 500 und | I18: =(J18*$J$6)+J18 -> 28.67 | J18: 28.67
A19: 1959 | B19: COMPRESSA DE GAZE NÃO ESTERIL | C19: 7,5 X 7,5 - 15x30 (aberta) | D19: 13 fios | E19: 32 | F19: EXTRA | G19: Medtextil | H19: 500 und | I19: =(J19*$J$6)+J19 -> 30.77 | J19: 30.77
A21: COMPRESSAS HIDRÓFILA CIRCULAR – TIPO QUEIJO
A22: 85 | B22: GAZE HIDROFILA CIRCULAR | C22: Tipo Queijo 91 | D22: 9 fios | E22: 36 | F22: COMBATE | G22: Med Mais | H22: 210gr | I22: =(J22*$J$6)+J22 -> 15.44 | J22: 15.44
A23: 263 | B23: GAZE HIDROFILA CIRCULAR | C23: Tipo Queijo 91 | D23: 11 fios | E23: 30 | F23: COMBATE | G23: Med Mais | H23: 250gr | I23: =(J23*$J$6)+J23 -> 18.86 | J23: 18.86
A24: 279 | B24: GAZE HIDROFILA CIRCULAR | C24: Tipo Queijo 91 | D24: 13 fios | E24: 30 | F24: COMBATE | G24: Med Mais | H24: 270gr | I24: =(J24*$J$6)+J24 -> 19.88 | J24: 19.88
A25: 94 | B25: GAZE HIDROFILA CIRCULAR | C25: Tipo Queijo 91 | D25: 9 fios | E25: 30 | F25: INTERMEDIARIA | G25: Med Mais | H25: 300gr | I25: =(J25*$J$6)+J25 -> 22.8 | J25: 22.8
A26: 271 | B26: GAZE HIDROFILA CIRCULAR | C26: Tipo Queijo 91 | D26: 11 fios | E26: 25 | F26: INTERMEDIARIA | G26: Med Mais | H26: 320gr | I26: =(J26*$J$6)+J26 -> 24.86 | J26: 24.86
A27: 286 | B27: GAZE HIDROFILA CIRCULAR | C27: Tipo Queijo 91 | D27: 13 fios | E27: 25 | F27: INTERMEDIARIA | G27: Med Mais | H27: 340gr | I27: =(J27*$J$6)+J27 -> 26.86 | J27: 26.86
A28: 132 | B28: GAZE HIDROFILA CIRCULAR | C28: Tipo Queijo 91 | D28: 9 fios | E28: 20 | F28: EXTRA | G28: Ultra Têxtil | H28: 370gr | I28: =(J28*$J$6)+J28 -> 29.67 | J28: 29.67
A29: 294 | B29: GAZE HIDROFILA CIRCULAR | C29: Tipo Queijo 91 | D29: 11 fios | E29: 20 | F29: EXTRA | G29: Ultra Têxtil | H29: 380gr | I29: =(J29*$J$6)+J29 -> 30.58 | J29: 30.58
A30: 300 | B30: GAZE HIDROFILA CIRCULAR | C30: Tipo Queijo 91 | D30: 13 fios | E30: 20 | F30: EXTRA | G30: Ultra Têxtil | H30: 410gr | I30: =(J30*$J$6)+J30 -> 32.94 | J30: 32.94
A31: 1960 | B31: GAZE HIDROFILA CIRCULAR | C31: Tipo Queijo 91cm x 91m | D31: 9 fios | F31: EXTRA | G31: Medtextil | H31: 1.460gr | I31: =(J31*$J$6)+J31 -> 94.88 | J31: 94.88
A32: 1961 | B32: GAZE HIDROFILA CIRCULAR | C32: Tipo Queijo 91cm x 91m | D32: 11 fios | F32: EXTRA | G32: Medtextil | H32: 1.530gr | I32: =(J32*$J$6)+J32 -> 98.7 | J32: 98.7
A33: 1962 | B33: GAZE HIDROFILA CIRCULAR | C33: Tipo Queijo 91cm x 91m | D33: 13 fios | F33: EXTRA | G33: Medtextil | H33: 1.650gr | I33: =(J33*$J$6)+J33 -> 107.44 | J33: 107.44
A39: COMPRESSA ESTÉRIL
A40: 1 | B40: COMPRESSA ESTÉRIL – 9FIOS | C40: PCT 10 UND | D40: 9 fios | E40: 1000 | F40: COMBATE | G40: Med Mais | I40: =(J40*$J$6)+J40 -> 0.38 | J40: 0.38
A41: 2 | B41: COMPRESSA ESTÉRIL – 11FIOS | C41: PCT 10 UND | D41: 11 fios | E41: 1000 | F41: COMBATE | G41: Med Mais | I41: =(J41*$J$6)+J41 -> 0.4 | J41: 0.4
A42: 3 | B42: COMPRESSA ESTÉRIL – 13FIOS | C42: PCT 10 UND | D42: 13 fios | E42: 1000 | F42: COMBATE | G42: Med Mais | I42: =(J42*$J$6)+J42 -> 0.42 | J42: 0.42
A43: 152 | B43: COMPRESSA ESTÉRIL – 9FIOS | C43: PCT 10 UND | D43: 9 fios | E43: 1000 | F43: INTERMEDIARIA | G43: Ultra Têxtil | I43: =(J43*$J$6)+J43 -> 0.44 | J43: 0.44
A44: 153 | B44: COMPRESSA ESTÉRIL – 11FIOS | C44: PCT 10 UND | D44: 11 fios | E44: 1000 | F44: INTERMEDIARIA | G44: Ultra Têxtil | I44: =(J44*$J$6)+J44 -> 0.47 | J44: 0.47
A45: 154 | B45: COMPRESSA ESTÉRIL – 13FIOS | C45: PCT 10 UND | D45: 13 fios | E45: 1000 | F45: INTERMEDIARIA | G45: Ultra Têxtil | I45: =(J45*$J$6)+J45 -> 0.49 | J45: 0.49
A46: 1641 | B46: COMPRESSA ESTÉRIL – 9FIOS 7,50 X 7,50 | C46: PCT 10 UND | D46: 9 fios | E46: 1000 | F46: EXTRA | G46: MedTextil | I46: =(J46*$J$6)+J46 -> 0.6 | J46: 0.6
A47: 1642 | B47: COMPRESSA ESTÉRIL – 11FIOS 7,50 X 7,50 | C47: PCT 10 UND | D47: 11 fios | E47: 1000 | F47: EXTRA | G47: MedTextil | I47: =(J47*$J$6)+J47 -> 0.62 | J47: 0.62
A48: 1643 | B48: COMPRESSA ESTÉRIL – 13FIOS 7,50 X 7,50 | C48: PCT 10 UND | D48: 13 fios | E48: 1000 | F48: EXTRA | G48: MedTextil | I48: =(J48*$J$6)+J48 -> 0.65 | J48: 0.65
A50: CAMPOS OPERATÓRIOS
A51: 1586 | B51: CAMPO OPERATÓRIO - LEVE | C51: 45X50 PCT C/50 | E51: 12 | F51: Com Radiopaco | G51: Med Mais | H51: 15gr | I51: =(J51*$J$6)+J51 -> 49.5 | J51: 49.5
...

Sheet TAB 4%
A1: TABELA DE PREÇOS
A5: COMPRESSAS DE GAZES – PACOTE
A6: CÓD. | B6: PRODUTO | C6: APRESENTAÇÃO | E6: UND CAIXA | F6: LINHA | G6: MARCA | H6: GRAMAT | I6: PREÇO | J6: 0.06
A8: 8 | B8: COMPRESSA DE GAZE NÃO ESTERIL | C8: PACOTE 105gr | D8: 9 fios | E8: 72 | F8: COMBATE | G8: Med Mais | H8: 105gr | I8: =(J8*$J$6)+J8 -> 7.4094 | J8: 6.99
A9: 310 | B9: COMPRESSA DE GAZE NÃO ESTERIL | C9: PACOTE 130gr | D9: 11 fios | E9: 60 | F9: COMBATE | G9: Med Mais | H9: 130gr | I9: =(J9*$J$6)+J9 -> 10.3244 | J9: 9.74
A10: 326 | B10: COMPRESSA DE GAZE NÃO ESTERIL | C10: PACOTE 150gr | D10: 13 fios | E10: 50 | F10: COMBATE | G10: Med Mais | H10: 150gr | I10: =(J10*$J$6)+J10 -> 12.561 | J10: 11.85
A11: 13 | B11: COMPRESSA DE GAZE NÃO ESTERIL | C11: PACOTE 150gr | D11: 9 fios | E11: 50 | F11: INTERMEDIARIA | G11: Med Mais | H11: 150gr | I11: =(J11*$J$6)+J11 -> 11.5328 | J11: 10.88
A12: 313 | B12: COMPRESSA DE GAZE NÃO ESTERIL | C12: PACOTE 160gr | D12: 11 fios | E12: 50 | F12: INTERMEDIARIA | G12: Med Mais | H12: 160gr | I12: =(J12*$J$6)+J12 -> 12.6988 | J12: 11.98
A13: 329 | B13: COMPRESSA DE GAZE NÃO ESTERIL | C13: PACOTE 180gr | D13: 13 fios | E13: 50 | F13: INTERMEDIARIA | G13: Med Mais | H13: 180gr | I13: =(J13*$J$6)+J13 -> 15.0732 | J13: 14.22
A14: 51 | B14: COMPRESSA DE GAZE NÃO ESTERIL | C14: 7,5 X 7,5 - 15x26 (aberta) | D14: 9 fios | E14: 40 | F14: EXTRA | G14: Ultra Têxtil | H14: 500 und | I14: =(J14*$J$6)+J14 -> 15.3276 | J14: 14.46
A15: 339 | B15: COMPRESSA DE GAZE NÃO ESTERIL | C15: 7,5 X 7,5 - 15x26 (aberta) | D15: 11 fios | E15: 32 | F15: EXTRA | G15: Ultra Têxtil | H15: 500 und | I15: =(J15*$J$6)+J15 -> 17.5748 | J15: 16.58
A16: 349 | B16: COMPRESSA DE GAZE NÃO ESTERIL | C16: 7,5 X 7,5 - 15x26 (aberta) | D16: 13 fios | E16: 32 | F16: EXTRA | G16: Ultra Têxtil | H16: 500 und | I16: =(J16*$J$6)+J16 -> 20.3732 | J16: 19.22
A17: 1957 | B17: COMPRESSA DE GAZE NÃO ESTERIL | C17: 7,5 X 7,5 - 15x30 (aberta) | D17: 9 fios | E17: 40 | F17: EXTRA | G17: Medtextil | H17: 500 und | I17: =(J17*$J$6)+J17 -> 29.5528 | J17: 27.88
A18: 1958 | B18: COMPRESSA DE GAZE NÃO ESTERIL | C18: 7,5 X 7,5 - 15x30 (aberta) | D18: 11 fios | E18: 32 | F18: EXTRA | G18: Medtextil | H18: 500 und | I18: =(J18*$J$6)+J18 -> 30.3902 | J18: 28.67
A19: 1959 | B19: COMPRESSA DE GAZE NÃO ESTERIL | C19: 7,5 X 7,5 - 15x30 (aberta) | D19: 13 fios | E19: 32 | F19: EXTRA | G19: Medtextil | H19: 500 und | I19: =(J19*$J$6)+J19 -> 32.6162 | J19: 30.77
A21: COMPRESSAS HIDRÓFILA CIRCULAR – TIPO QUEIJO
A22: 85 | B22: GAZE HIDROFILA CIRCULAR | C22: Tipo Queijo 91 | D22: 9 fios | E22: 36 | F22: COMBATE | G22: Med Mais | H22: 210gr | I22: =(J22*$J$6)+J22 -> 16.3664 | J22: 15.44
A23: 263 | B23: GAZE HIDROFILA CIRCULAR | C23: Tipo Queijo 91 | D23: 11 fios | E23: 30 | F23: COMBATE | G23: Med Mais | H23: 250gr | I23: =(J23*$J$6)+J23 -> 19.9916 | J23: 18.86
A24: 279 | B24: GAZE HIDROFILA CIRCULAR | C24: Tipo Queijo 91 | D24: 13 fios | E24: 30 | F24: COMBATE | G24: Med Mais | H24: 270gr | I24: =(J24*$J$6)+J24 -> 21.0728 | J24: 19.88
A25: 94 | B25: GAZE HIDROFILA CIRCULAR | C25: Tipo Queijo 91 | D25: 9 fios | E25: 30 | F25: INTERMEDIARIA | G25: Med Mais | H25: 300gr | I25: =(J25*$J$6)+J25 -> 24.168 | J25: 22.8
A26: 271 | B26: GAZE HIDROFILA CIRCULAR | C26: Tipo Queijo 91 | D26: 11 fios | E26: 25 | F26: INTERMEDIARIA | G26: Med Mais | H26: 320gr | I26: =(J26*$J$6)+J26 -> 26.3516 | J26: 24.86
A27: 286 | B27: GAZE HIDROFILA CIRCULAR | C27: Tipo Queijo 91 | D27: 13 fios | E27: 25 | F27: INTERMEDIARIA | G27: Med Mais | H27: 340gr | I27: =(J27*$J$6)+J27 -> 28.4716 | J27: 26.86
A28: 132 | B28: GAZE HIDROFILA CIRCULAR | C28: Tipo Queijo 91 | D28: 9 fios | E28: 20 | F28: EXTRA | G28: Ultra Têxtil | H28: 370gr | I28: =(J28*$J$6)+J28 -> 31.4502 | J28: 29.67
A29: 294 | B29: GAZE HIDROFILA CIRCULAR | C29: Tipo Queijo 91 | D29: 11 fios | E29: 20 | F29: EXTRA | G29: Ultra Têxtil | H29: 380gr | I29: =(J29*$J$6)+J29 -> 32.4148 | J29: 30.58
A30: 300 | B30: GAZE HIDROFILA CIRCULAR | C30: Tipo Queijo 91 | D30: 13 fios | E30: 20 | F30: EXTRA | G30: Ultra Têxtil | H30: 410gr | I30: =(J30*$J$6)+J30 -> 34.9164 | J30: 32.94
A31: 1960 | B31: GAZE HIDROFILA CIRCULAR | C31: Tipo Queijo 91cm x 91m | D31: 9 fios | F31: EXTRA | G31: Medtextil | H31: 1.460gr | I31: =(J31*$J$6)+J31 -> 100.5728 | J31: 94.88
A32: 1961 | B32: GAZE HIDROFILA CIRCULAR | C32: Tipo Queijo 91cm x 91m | D32: 11 fios | F32: EXTRA | G32: Medtextil | H32: 1.530gr | I32: =(J32*$J$6)+J32 -> 104.622 | J32: 98.7
A33: 1962 | B33: GAZE HIDROFILA CIRCULAR | C33: Tipo Queijo 91cm x 91m | D33: 13 fios | F33: EXTRA | G33: Medtextil | H33: 1.650gr | I33: =(J33*$J$6)+J33 -> 113.8864 | J33: 107.44
A39: COMPRESSA ESTÉRIL
A40: 1 | B40: COMPRESSA ESTÉRIL – 9FIOS | C40: PCT 10 UND | D40: 9 fios | E40: 1000 | F40: COMBATE | G40: Med Mais | I40: =(J40*$J$6)+J40 -> 0.4028 | J40: 0.38
A41: 2 | B41: COMPRESSA ESTÉRIL – 11FIOS | C41: PCT 10 UND | D41: 11 fios | E41: 1000 | F41: COMBATE | G41: Med Mais | I41: =(J41*$J$6)+J41 -> 0.424 | J41: 0.4
A42: 3 | B42: COMPRESSA ESTÉRIL – 13FIOS | C42: PCT 10 UND | D42: 13 fios | E42: 1000 | F42: COMBATE | G42: Med Mais | I42: =(J42*$J$6)+J42 -> 0.4452 | J42: 0.42
A43: 152 | B43: COMPRESSA ESTÉRIL – 9FIOS | C43: PCT 10 UND | D43: 9 fios | E43: 1000 | F43: INTERMEDIARIA | G43: Ultra Têxtil | I43: =(J43*$J$6)+J43 -> 0.4664 | J43: 0.44
A44: 153 | B44: COMPRESSA ESTÉRIL – 11FIOS | C44: PCT 10 UND | D44: 11 fios | E44: 1000 | F44: INTERMEDIARIA | G44: Ultra Têxtil | I44: =(J44*$J$6)+J44 -> 0.4982 | J44: 0.47
A45: 154 | B45: COMPRESSA ESTÉRIL – 13FIOS | C45: PCT 10 UND | D45: 13 fios | E45: 1000 | F45: INTERMEDIARIA | G45: Ultra Têxtil | I45: =(J45*$J$6)+J45 -> 0.5194 | J45: 0.49
A46: 1641 | B46: COMPRESSA ESTÉRIL – 9FIOS 7,50 X 7,50 | C46: PCT 10 UND | D46: 9 fios | E46: 1000 | F46: EXTRA | G46: MedTextil | I46: =(J46*$J$6)+J46 -> 0.636 | J46: 0.6
A47: 1642 | B47: COMPRESSA ESTÉRIL – 11FIOS 7,50 X 7,50 | C47: PCT 10 UND | D47: 11 fios | E47: 1000 | F47: EXTRA | G47: MedTextil | I47: =(J47*$J$6)+J47 -> 0.6572 | J47: 0.62
A48: 1643 | B48: COMPRESSA ESTÉRIL – 13FIOS 7,50 X 7,50 | C48: PCT 10 UND | D48: 13 fios | E48: 1000 | F48: EXTRA | G48: MedTextil | I48: =(J48*$J$6)+J48 -> 0.689 | J48: 0.65
A50: CAMPOS OPERATÓRIOS
A51: 1586 | B51: CAMPO OPERATÓRIO - LEVE | C51: 45X50 PCT C/50 | F51: Com Radiopaco | G51: Med Mais | H51: 15gr | I51: =(J51*$J$6)+J51 -> 52.47 | J51: 49.5
...

Sheet Tabela_3%
A3: TABELA DE PREÇOS
A6: COMPRESSAS DE GAZES – PACOTE
A7: CÓD. | B7: PRODUTO | C7: APRESENTAÇÃO | D7: FIOS | E7: UND CAIXA | F7: MARCA | G7: GRAMAT | H7: PREÇO | I7: 0
A9: 8 | B9: COMPRESSA DE GAZE NÃO ESTERIL | C9: 7,5 X 7,5 - 13x24 (aberta) | D9: 9 fios | E9: 72 | F9: Med Mais | G9: 105gr | H9: =(I9*$I$7)+I9 -> 6.99 | I9: 6.99
A10: 310 | B10: COMPRESSA DE GAZE NÃO ESTERIL | C10: 7,5 X 7,5 - 13x24 (aberta) | D10: 11 fios | E10: 60 | F10: Med Mais | G10: 130gr | H10: =(I10*$I$7)+I10 -> 9.74 | I10: 9.74
A11: 326 | B11: COMPRESSA DE GAZE NÃO ESTERIL | C11: 7,5 X 7,5 - 13x24 (aberta) | D11: 13 fios | E11: 50 | F11: Med Mais | G11: 150gr | H11: =(I11*$I$7)+I11 -> 11.85 | I11: 11.85
A12: 13 | B12: COMPRESSA DE GAZE NÃO ESTERIL | C12: 7,5 X 7,5 - 13x24 (aberta) | D12: 9 fios | E12: 50 | F12: Med Mais | G12: 150gr | H12: =(I12*$I$7)+I12 -> 10.88 | I12: 10.88
A13: 313 | B13: COMPRESSA DE GAZE NÃO ESTERIL | C13: 7,5 X 7,5 - 13x24 (aberta) | D13: 11 fios | E13: 50 | F13: Med Mais | G13: 160gr | H13: =(I13*$I$7)+I13 -> 11.98 | I13: 11.98
A14: 329 | B14: COMPRESSA DE GAZE NÃO ESTERIL | C14: 7,5 X 7,5 - 13x24 (aberta) | D14: 13 fios | E14: 50 | F14: Med Mais | G14: 180gr | H14: =(I14*$I$7)+I14 -> 14.22 | I14: 14.22
A16: COMPRESSAS HIDRÓFILA CIRCULAR – TIPO QUEIJO
A17: 85 | B17: GAZE HIDROFILA CIRCULAR | C17: Tipo Queijo 91 | D17: 9 fios | E17: 36 | F17: Med Mais | G17: 210gr | H17: =(I17*$I$7)+I17 -> 15.44 | I17: 15.44
A18: 263 | B18: GAZE HIDROFILA CIRCULAR | C18: Tipo Queijo 91 | D18: 11 fios | E18: 30 | F18: Med Mais | G18: 250gr | H18: =(I18*$I$7)+I18 -> 18.86 | I18: 18.86
A19: 279 | B19: GAZE HIDROFILA CIRCULAR | C19: Tipo Queijo 91 | D19: 13 fios | E19: 30 | F19: Med Mais | G19: 270gr | H19: =(I19*$I$7)+I19 -> 19.88 | I19: 19.88
A20: 94 | B20: GAZE HIDROFILA CIRCULAR | C20: Tipo Queijo 91 | D20: 9 fios | E20: 30 | F20: Med Mais | G20: 300gr | H20: =(I20*$I$7)+I20 -> 22.8 | I20: 22.8
A21: 271 | B21: GAZE HIDROFILA CIRCULAR | C21: Tipo Queijo 91 | D21: 11 fios | E21: 25 | F21: Med Mais | G21: 320gr | H21: =(I21*$I$7)+I21 -> 24.86 | I21: 24.86
A22: 286 | B22: GAZE HIDROFILA CIRCULAR | C22: Tipo Queijo 91 | D22: 13 fios | E22: 25 | F22: Med Mais | G22: 340gr | H22: =(I22*$I$7)+I22 -> 26.86 | I22: 26.86
A24: COMPRESSA ESTÉRIL
A25: 1 | B25: COMPRESSA ESTÉRIL – 9FIOS | C25: 7,5 X 7,5 - 13x24 (aberta) | D25: 9 fios | E25: 1000 | F25: Med Mais | H25: =(I25*$I$7)+I25 -> 0.38 | I25: 0.38
A26: 2 | B26: COMPRESSA ESTÉRIL – 11FIOS | C26: 7,5 X 7,5 - 13x24 (aberta) | D26: 11 fios | E26: 1000 | F26: Med Mais | H26: =(I26*$I$7)+I26 -> 0.4 | I26: 0.4
A27: 3 | B27: COMPRESSA ESTÉRIL – 13FIOS | C27: 7,5 X 7,5 - 13x24 (aberta) | D27: 13 fios | E27: 1000 | F27: Med Mais | H27: =(I27*$I$7)+I27 -> 0.42 | I27: 0.42
A29: CAMPO OPERATÓRIO - NÃO ESTÉRIL | C29: 45X50
A30: 1586 | B30: CAMPO OPERATÓRIO 45X50 (Com Radiopaco) | C30: PCT C/50 | E30: 12 | F30: Med Mais | H30: =(I30*$I$7)+I30 -> 49.5 | I30: 49.5
A31: 1797 | B31: CAMPO OPERATÓRIO 45X50 (Sem Radiopaco) | C31: PCT C/50 | E31: 12 | F31: Med Mais | H31: =(I31*$I$7)+I31 -> 48.5 | I31: 48.5
A33: CAMPO OPERATÓRIO - ESTÉRIL | C33: 25X28
A34: 1588 | B34: CAMPO OPERATÓRIO – Pré encolhido | C34: PCT C/5 UND | E34: 150 | F34: Med Mais | H34: =(I34*$I$7)+I34 -> 5.18 | I34: 5.18
A35: 1587 | B35: CAMPO OPERATÓRIO – Pré encolhido | C35: PCT C/2 UND | E35: 300 | F35: Med Mais | H35: =(I35*$I$7)+I35 -> 2.8 | I35: 2.8
A37: ATADURAS - LINHA FARMA
A38: 1644 | B38: ATADURA DE CREPE | C38: 08CM x 1,20M | D38: 13 FIOS | E38: 115 DUZIAS | F38: Med Mais | H38: =(I38*$I$7)+I38 -> 3.66 | I38: 3.66
A39: 1589 | B39: ATADURA DE CREPE | C39: 10CM x 1,20M | D39: 13 FIOS | E39: 110 DUZIAS | F39: Med Mais | H39: =(I39*$I$7)+I39 -> 3.97 | I39: 3.97
A40: 1590 | B40: ATADURA DE CREPE | C40: 12CM x 1,20M | D40: 13 FIOS | E40: 110 DUZIAS | F40: Med Mais | H40: =(I40*$I$7)+I40 -> 4.91 | I40: 4.91
A41: 1592 | B41: ATADURA DE CREPE | C41: 15CM x 1,20M | D41: 13 FIOS | E41: 90 DUZIAS | F41: Med Mais | H41: =(I41*$I$7)+I41 -> 5.63 | I41: 5.63
A42: 1593 | B42: ATADURA DE CREPE | C42: 20CM x 1,20M | D42: 13 FIOS | E42: 70 DUZIAS | F42: Med Mais | H42: =(I42*$I$7)+I42 -> 7.25 | I42: 7.25
A43: 1594 | B43: ATADURA DE CREPE | C43: 30CM x 1,20M | D43: 13 FIOS | E43: 50 DUZIAS | F43: Med Mais | H43: =(I43*$I$7)+I43 -> 10.74 | I43: 10.74
A44: 1973 | B44: ATADURA DE CREPE | C44: 08CM x 1,80M | D44: 13 FIOS | E44: 105 DUZIAS | F44: Med Mais | H44: =(I44*$I$7)+I44 -> 4.96 | I44: 4.96
A45: 1595 | B45: ATADURA DE CREPE | C45: 10CM x 1,80M | D45: 13 FIOS | E45: 100 DUZIAS | F45: Med Mais | H45: =(I45*$I$7)+I45 -> 5.38 | I45: 5.38
A46: 1596 | B46: ATADURA DE CREPE | C46: 12CM x 1,80M | D46: 13 FIOS | E46: 90 DUZIAS | F46: Med Mais | H46: =(I46*$I$7)+I46 -> 6.78 | I46: 6.78
A47: 1597 | B47: ATADURA DE CREPE | C47: 15CM x 1,80M | D47: 13 FIOS | E47: 75 DUZIAS | F47: Med Mais | H47: =(I47*$I$7)+I47 -> 7.94 | I47: 7.94
A48: 1598 | B48: ATADURA DE CREPE | C48: 20CM x 1,80M | D48: 13 FIOS | E48: 60 DUZIAS | F48: Med Mais | H48: =(I48*$I$7)+I48 -> 10.3 | I48: 10.3
A49: 1599 | B49: ATADURA DE CREPE | C49: 30CM x 1,80M | D49: 13 FIOS | E49: 40 DUZIAS | F49: Med Mais | H49: =(I49*$I$7)+I49 -> 14.74 | I49: 14.74
A51: ATADURAS - LINHA HOSPITALAR
...

Sheet Tabela_4%
A1: TABELA DE PREÇOS
A6: COMPRESSAS DE GAZES – PACOTE
A7: CÓD. | B7: PRODUTO | C7: APRESENTAÇÃO | E7: UND CAIXA | F7: MARCA | G7: GRAMAT | H7: PREÇO | I7: 0.06
A9: 8 | B9: COMPRESSA DE GAZE NÃO ESTERIL | C9: 7,5 X 7,5 - 13x24 (aberta) | D9: 9 fios | E9: 72 | F9: Med Mais | G9: 105gr | H9: =(I9*$I$7)+I9 -> 7.4094 | I9: ='Tabela_3%'!H9 -> 6.99
A10: 310 | B10: COMPRESSA DE GAZE NÃO ESTERIL | C10: 7,5 X 7,5 - 13x24 (aberta) | D10: 11 fios | E10: 60 | F10: Med Mais | G10: 130gr | H10: =(I10*$I$7)+I10 -> 10.3244 | I10: ='Tabela_3%'!H10 -> 9.74
A11: 326 | B11: COMPRESSA DE GAZE NÃO ESTERIL | C11: 7,5 X 7,5 - 13x24 (aberta) | D11: 13 fios | E11: 50 | F11: Med Mais | G11: 150gr | H11: =(I11*$I$7)+I11 -> 12.561 | I11: ='Tabela_3%'!H11 -> 11.85
A12: 13 | B12: COMPRESSA DE GAZE NÃO ESTERIL | C12: 7,5 X 7,5 - 13x24 (aberta) | D12: 9 fios | E12: 50 | F12: Med Mais | G12: 150gr | H12: =(I12*$I$7)+I12 -> 11.5328 | I12: ='Tabela_3%'!H12 -> 10.88
A13: 313 | B13: COMPRESSA DE GAZE NÃO ESTERIL | C13: 7,5 X 7,5 - 13x24 (aberta) | D13: 11 fios | E13: 50 | F13: Med Mais | G13: 160gr | H13: =(I13*$I$7)+I13 -> 12.6988 | I13: ='Tabela_3%'!H13 -> 11.98
A14: 329 | B14: COMPRESSA DE GAZE NÃO ESTERIL | C14: 7,5 X 7,5 - 13x24 (aberta) | D14: 13 fios | E14: 50 | F14: Med Mais | G14: 180gr | H14: =(I14*$I$7)+I14 -> 15.0732 | I14: ='Tabela_3%'!H14 -> 14.22
I15: ='Tabela_3%'!H15 -> 0
A16: COMPRESSAS HIDRÓFILA CIRCULAR – TIPO QUEIJO | I16: ='Tabela_3%'!H16 -> 0
A17: 85 | B17: GAZE HIDROFILA CIRCULAR | C17: Tipo Queijo 91 | D17: 9 fios | E17: 36 | F17: Med Mais | G17: 210gr | H17: =(I17*$I$7)+I17 -> 16.3664 | I17: ='Tabela_3%'!H17 -> 15.44
A18: 263 | B18: GAZE HIDROFILA CIRCULAR | C18: Tipo Queijo 91 | D18: 11 fios | E18: 30 | F18: Med Mais | G18: 250gr | H18: =(I18*$I$7)+I18 -> 19.9916 | I18: ='Tabela_3%'!H18 -> 18.86
A19: 279 | B19: GAZE HIDROFILA CIRCULAR | C19: Tipo Queijo 91 | D19: 13 fios | E19: 30 | F19: Med Mais | G19: 270gr | H19: =(I19*$I$7)+I19 -> 21.0728 | I19: ='Tabela_3%'!H19 -> 19.88
A20: 94 | B20: GAZE HIDROFILA CIRCULAR | C20: Tipo Queijo 91 | D20: 9 fios | E20: 30 | F20: Med Mais | G20: 300gr | H20: =(I20*$I$7)+I20 -> 24.168 | I20: ='Tabela_3%'!H20 -> 22.8
A21: 271 | B21: GAZE HIDROFILA CIRCULAR | C21: Tipo Queijo 91 | D21: 11 fios | E21: 25 | F21: Med Mais | G21: 320gr | H21: =(I21*$I$7)+I21 -> 26.3516 | I21: ='Tabela_3%'!H21 -> 24.86
A22: 286 | B22: GAZE HIDROFILA CIRCULAR | C22: Tipo Queijo 91 | D22: 13 fios | E22: 25 | F22: Med Mais | G22: 340gr | H22: =(I22*$I$7)+I22 -> 28.4716 | I22: ='Tabela_3%'!H22 -> 26.86
I23: ='Tabela_3%'!H23 -> 0
A24: COMPRESSA ESTÉRIL | I24: ='Tabela_3%'!H24 -> 0
A25: 1 | B25: COMPRESSA ESTÉRIL – 9FIOS | C25: 7,5 X 7,5 - 13x24 (aberta) | D25: 9 fios | E25: 1000 | F25: Med Mais | H25: =(I25*$I$7)+I25 -> 0.4028 | I25: ='Tabela_3%'!H25 -> 0.38
A26: 2 | B26: COMPRESSA ESTÉRIL – 11FIOS | C26: 7,5 X 7,5 - 13x24 (aberta) | D26: 11 fios | E26: 1000 | F26: Med Mais | H26: =(I26*$I$7)+I26 -> 0.424 | I26: ='Tabela_3%'!H26 -> 0.4
A27: 3 | B27: COMPRESSA ESTÉRIL – 13FIOS | C27: 7,5 X 7,5 - 13x24 (aberta) | D27: 13 fios | E27: 1000 | F27: Med Mais | H27: =(I27*$I$7)+I27 -> 0.4452 | I27: ='Tabela_3%'!H27 -> 0.42
I28: ='Tabela_3%'!H28 -> 0
A29: CAMPO OPERATÓRIO - NÃO ESTÉRIL | C29: 45X50 | I29: ='Tabela_3%'!H29 -> 0
A30: 1586 | B30: CAMPO OPERATÓRIO 45X50 (Com Radiopaco) | C30: PCT C/50 | E30: 12 | F30: Med Mais | H30: =(I30*$I$7)+I30 -> 52.47 | I30: ='Tabela_3%'!H30 -> 49.5
A31: 1797 | B31: CAMPO OPERATÓRIO 45X50 (Sem Radiopaco) | C31: PCT C/50 | E31: 12 | F31: Med Mais | H31: =(I31*$I$7)+I31 -> 51.41 | I31: ='Tabela_3%'!H31 -> 48.5
I32: ='Tabela_3%'!H32 -> 0
A33: CAMPO OPERATÓRIO - ESTÉRIL | C33: 25X28 | I33: ='Tabela_3%'!H33 -> 0
A34: 1588 | B34: CAMPO OPERATÓRIO – Pré encolhido | C34: PCT C/5 UND | E34: 150 | F34: Med Mais | H34: =(I34*$I$7)+I34 -> 5.4908 | I34: ='Tabela_3%'!H34 -> 5.18
A35: 1587 | B35: CAMPO OPERATÓRIO – Pré encolhido | C35: PCT C/2 UND | E35: 300 | F35: Med Mais | H35: =(I35*$I$7)+I35 -> 2.968 | I35: ='Tabela_3%'!H35 -> 2.8
I36: ='Tabela_3%'!H36 -> 0
A37: ATADURAS - LINHA FARMA | I37: ='Tabela_3%'!H37 -> 0
A38: 1644 | B38: ATADURA DE CREPE | C38: 08CM x 1,20M | D38: 13 FIOS | E38: 115 DUZIAS | F38: Med Mais | H38: =(I38*$I$7)+I38 -> 3.8796 | I38: ='Tabela_3%'!H38 -> 3.66
A39: 1589 | B39: ATADURA DE CREPE | C39: 10CM x 1,20M | D39: 13 FIOS | E39: 110 DUZIAS | F39: Med Mais | H39: =(I39*$I$7)+I39 -> 4.2082 | I39: ='Tabela_3%'!H39 -> 3.97
A40: 1590 | B40: ATADURA DE CREPE | C40: 12CM x 1,20M | D40: 13 FIOS | E40: 110 DUZIAS | F40: Med Mais | H40: =(I40*$I$7)+I40 -> 5.2046 | I40: ='Tabela_3%'!H40 -> 4.91
A41: 1592 | B41: ATADURA DE CREPE | C41: 15CM x 1,20M | D41: 13 FIOS | E41: 90 DUZIAS | F41: Med Mais | H41: =(I41*$I$7)+I41 -> 5.9678 | I41: ='Tabela_3%'!H41 -> 5.63
A42: 1593 | B42: ATADURA DE CREPE | C42: 20CM x 1,20M | D42: 13 FIOS | E42: 70 DUZIAS | F42: Med Mais | H42: =(I42*$I$7)+I42 -> 7.685 | I42: ='Tabela_3%'!H42 -> 7.25
A43: 1594 | B43: ATADURA DE CREPE | C43: 30CM x 1,20M | D43: 13 FIOS | E43: 50 DUZIAS | F43: Med Mais | H43: =(I43*$I$7)+I43 -> 11.3844 | I43: ='Tabela_3%'!H43 -> 10.74
A44: 1973 | B44: ATADURA DE CREPE | C44: 08CM x 1,80M | D44: 13 FIOS | E44: 105 DUZIAS | F44: Med Mais | H44: =(I44*$I$7)+I44 -> 5.2576 | I44: ='Tabela_3%'!H44 -> 4.96
A45: 1595 | B45: ATADURA DE CREPE | C45: 10CM x 1,80M | D45: 13 FIOS | E45: 100 DUZIAS | F45: Med Mais | H45: =(I45*$I$7)+I45 -> 5.7028 | I45: ='Tabela_3%'!H45 -> 5.38
...

Sheet MedMais 3%
A1: TABELA DE PREÇOS - LINHA
A6: COMPRESSAS DE GAZES – PACOTE
A7: CÓD. | B7: PRODUTO | C7: APRESENTAÇÃO | E7: UND CAIXA | F7: MARCA | G7: GRAMAT | H7: PREÇO
A9: 8 | B9: COMPRESSA DE GAZE NÃO ESTERIL | C9: PACOTE 105gr | D9: 9 fios | E9: 72 | F9: Med Mais | G9: 105gr | H9: =(I9*$I$7)+I9 -> 6.99 | I9: 6.99
A10: 310 | B10: COMPRESSA DE GAZE NÃO ESTERIL | C10: PACOTE 130gr | D10: 11 fios | E10: 60 | F10: Med Mais | G10: 130gr | H10: =(I10*$I$7)+I10 -> 9.74 | I10: 9.74
A11: 326 | B11: COMPRESSA DE GAZE NÃO ESTERIL | C11: PACOTE 150gr | D11: 13 fios | E11: 50 | F11: Med Mais | G11: 150gr | H11: =(I11*$I$7)+I11 -> 11.85 | I11: 11.85
A12: 13 | B12: COMPRESSA DE GAZE NÃO ESTERIL | C12: PACOTE 150gr | D12: 9 fios | E12: 50 | F12: Med Mais | G12: 150gr | H12: =(I12*$I$7)+I12 -> 10.88 | I12: 10.88
A13: 313 | B13: COMPRESSA DE GAZE NÃO ESTERIL | C13: PACOTE 160gr | D13: 11 fios | E13: 50 | F13: Med Mais | G13: 160gr | H13: =(I13*$I$7)+I13 -> 11.98 | I13: 11.98
A14: 329 | B14: COMPRESSA DE GAZE NÃO ESTERIL | C14: PACOTE 180gr | D14: 13 fios | E14: 50 | F14: Med Mais | G14: 180gr | H14: =(I14*$I$7)+I14 -> 14.22 | I14: 14.22
A16: COMPRESSAS HIDRÓFILA CIRCULAR – TIPO QUEIJO
A17: 85 | B17: GAZE HIDROFILA CIRCULAR | C17: Tipo Queijo 91 | D17: 9 fios | E17: 36 | F17: Med Mais | G17: 210gr | H17: =(I17*$I$7)+I17 -> 15.44 | I17: 15.44
A18: 263 | B18: GAZE HIDROFILA CIRCULAR | C18: Tipo Queijo 91 | D18: 11 fios | E18: 30 | F18: Med Mais | G18: 250gr | H18: =(I18*$I$7)+I18 -> 18.86 | I18: 18.86
A19: 279 | B19: GAZE HIDROFILA CIRCULAR | C19: Tipo Queijo 91 | D19: 13 fios | E19: 30 | F19: Med Mais | G19: 270gr | H19: =(I19*$I$7)+I19 -> 19.88 | I19: 19.88
A20: 94 | B20: GAZE HIDROFILA CIRCULAR | C20: Tipo Queijo 91 | D20: 9 fios | E20: 30 | F20: Med Mais | G20: 300gr | H20: =(I20*$I$7)+I20 -> 22.8 | I20: 22.8
A21: 271 | B21: GAZE HIDROFILA CIRCULAR | C21: Tipo Queijo 91 | D21: 11 fios | E21: 25 | F21: Med Mais | G21: 320gr | H21: =(I21*$I$7)+I21 -> 24.86 | I21: 24.86
A22: 286 | B22: GAZE HIDROFILA CIRCULAR | C22: Tipo Queijo 91 | D22: 13 fios | E22: 25 | F22: Med Mais | G22: 340gr | H22: =(I22*$I$7)+I22 -> 26.86 | I22: 26.86
A24: COMPRESSA ESTÉRIL
A25: 1 | B25: COMPRESSA ESTÉRIL – 9FIOS | C25: PCT 10 UND | D25: 9 fios | E25: 1000 | F25: Med Mais | H25: =(I25*$I$7)+I25 -> 0.38 | I25: 0.38
A26: 2 | B26: COMPRESSA ESTÉRIL – 11FIOS | C26: PCT 10 UND | D26: 11 fios | E26: 1000 | F26: Med Mais | H26: =(I26*$I$7)+I26 -> 0.4 | I26: 0.4
A27: 3 | B27: COMPRESSA ESTÉRIL – 13FIOS | C27: PCT 10 UND | D27: 13 fios | E27: 1000 | F27: Med Mais | H27: =(I27*$I$7)+I27 -> 0.42 | I27: 0.42
A29: CAMPOS OPERATÓRIOS
A30: 1586 | B30: CAMPO OPERATÓRIO - LEVE (Com Radiopaco | C30: 45X50 PCT C/50 | E30: 12 | F30: Med Mais | H30: =(I30*$I$7)+I30 -> 49.5 | I30: 49.5
A31: 1797 | B31: CAMPO OPERATÓRIO - LEVE (Sem Radiopaco) | C31: 45X50 PCT C/50 | E31: 12 | F31: Med Mais | H31: =(I31*$I$7)+I31 -> 48.5 | I31: 48.5
A32: 1588 | B32: CAMPO OPERATÓRIO – Pré encolhido | C32: 25X28 PCT C/5 UND | E32: 150 | F32: Med Mais | H32: =(I32*$I$7)+I32 -> 5.18 | I32: 5.18
A33: 1587 | B33: CAMPO OPERATÓRIO – Pré encolhido | C33: 25X28 PCT C/2 UND | E33: 300 | F33: Med Mais | H33: =(I33*$I$7)+I33 -> 2.8 | I33: 2.8
A35: ATADURAS - LINHA FARMA
A36: 163 | B36: ATADURA DE CREPE | C36: 10CM x 1,20M | D36: 13 FIOS | E36: 110 DUZIAS | F36: Med Mais | H36: =(I36*$I$7)+I36 -> 4.46 | I36: 4.46
A37: 480 | B37: ATADURA DE CREPE | C37: 12CM x 1,20M | D37: 13 FIOS | E37: 110 DUZIAS | F37: Med Mais | H37: =(I37*$I$7)+I37 -> 5.51 | I37: 5.51
A38: 164 | B38: ATADURA DE CREPE | C38: 15CM x 1,20M | D38: 13 FIOS | E38: 90 DUZIAS | F38: Med Mais | H38: =(I38*$I$7)+I38 -> 6.32 | I38: 6.32
A39: 165 | B39: ATADURA DE CREPE | C39: 20CM x 1,20M | D39: 13 FIOS | E39: 70 DUZIAS | F39: Med Mais | H39: =(I39*$I$7)+I39 -> 8.14 | I39: 8.14
A40: 166 | B40: ATADURA DE CREPE | C40: 30CM x 1,20M | D40: 13 FIOS | E40: 50 DUZIAS | F40: Med Mais | H40: =(I40*$I$7)+I40 -> 12.06 | I40: 12.06
A41: 171 | B41: ATADURA DE CREPE | C41: 10CM x 1,80M | D41: 13 FIOS | E41: 100 DUZIAS | F41: Med Mais | H41: =(I41*$I$7)+I41 -> 6.05 | I41: 6.05
A42: 478 | B42: ATADURA DE CREPE | C42: 12CM x 1,80M | D42: 13 FIOS | E42: 90 DUZIAS | F42: Med Mais | H42: =(I42*$I$7)+I42 -> 7.62 | I42: 7.62
A43: 172 | B43: ATADURA DE CREPE | C43: 15CM x 1,80M | D43: 13 FIOS | E43: 75 DUZIAS | F43: Med Mais | H43: =(I43*$I$7)+I43 -> 8.91 | I43: 8.91
A44: 173 | B44: ATADURA DE CREPE | C44: 20CM x 1,80M | D44: 13 FIOS | E44: 60 DUZIAS | F44: Med Mais | H44: =(I44*$I$7)+I44 -> 11.57 | I44: 11.57
A45: 174 | B45: ATADURA DE CREPE | C45: 30CM x 1,80M | D45: 13 FIOS | E45: 40 DUZIAS | F45: Med Mais | H45: =(I45*$I$7)+I45 -> 16.57 | I45: 16.57
A47: ATADURAS - LINHA HOSPITALAR
A48: 414 | B48: ATADURA DE CREPE | C48: 10CM x 1,20M | D48: 13 FIOS | E48: 110 DUZIAS | F48: Med Mais | H48: =(I48*$I$7)+I48 -> 4.32 | I48: 4.32
A49: 476 | B49: ATADURA DE CREPE | C49: 12CM x 1,20M | D49: 13 FIOS | E49: 104 DUZIAS | F49: Med Mais | H49: =(I49*$I$7)+I49 -> 5.34 | I49: 5.34
A50: 419 | B50: ATADURA DE CREPE | C50: 15CM x 1,20M | D50: 13 FIOS | E50: 70 DUZIAS | F50: Med Mais | H50: =(I50*$I$7)+I50 -> 6.15 | I50: 6.15
...

Sheet MedMais 4%
A1: TABELA DE PREÇOS - LINHA
A6: COMPRESSAS DE GAZES – PACOTE
A7: CÓD. | B7: PRODUTO | C7: APRESENTAÇÃO | E7: UND CAIXA | F7: MARCA | G7: GRAMAT | H7: PREÇO | I7: 0.06
A9: 8 | B9: COMPRESSA DE GAZE NÃO ESTERIL | C9: PACOTE 105gr | D9: 9 fios | E9: 72 | F9: Med Mais | G9: 105gr | H9: =(I9*$I$7)+I9 -> 7.4094 | I9: 6.99
A10: 310 | B10: COMPRESSA DE GAZE NÃO ESTERIL | C10: PACOTE 130gr | D10: 11 fios | E10: 60 | F10: Med Mais | G10: 130gr | H10: =(I10*$I$7)+I10 -> 10.3244 | I10: 9.74
A11: 326 | B11: COMPRESSA DE GAZE NÃO ESTERIL | C11: PACOTE 150gr | D11: 13 fios | E11: 50 | F11: Med Mais | G11: 150gr | H11: =(I11*$I$7)+I11 -> 12.561 | I11: 11.85
A12: 13 | B12: COMPRESSA DE GAZE NÃO ESTERIL | C12: PACOTE 150gr | D12: 9 fios | E12: 50 | F12: Med Mais | G12: 150gr | H12: =(I12*$I$7)+I12 -> 11.5328 | I12: 10.88
A13: 313 | B13: COMPRESSA DE GAZE NÃO ESTERIL | C13: PACOTE 160gr | D13: 11 fios | E13: 50 | F13: Med Mais | G13: 160gr | H13: =(I13*$I$7)+I13 -> 12.6988 | I13: 11.98
A14: 329 | B14: COMPRESSA DE GAZE NÃO ESTERIL | C14: PACOTE 180gr | D14: 13 fios | E14: 50 | F14: Med Mais | G14: 180gr | H14: =(I14*$I$7)+I14 -> 15.0732 | I14: 14.22
A16: COMPRESSAS HIDRÓFILA CIRCULAR – TIPO QUEIJO
A17: 85 | B17: GAZE HIDROFILA CIRCULAR | C17: Tipo Queijo 91 | D17: 9 fios | E17: 36 | F17: Med Mais | G17: 210gr | H17: =(I17*$I$7)+I17 -> 16.3664 | I17: 15.44
A18: 263 | B18: GAZE HIDROFILA CIRCULAR | C18: Tipo Queijo 91 | D18: 11 fios | E18: 30 | F18: Med Mais | G18: 250gr | H18: =(I18*$I$7)+I18 -> 19.9916 | I18: 18.86
A19: 279 | B19: GAZE HIDROFILA CIRCULAR | C19: Tipo Queijo 91 | D19: 13 fios | E19: 30 | F19: Med Mais | G19: 270gr | H19: =(I19*$I$7)+I19 -> 21.0728 | I19: 19.88
A20: 94 | B20: GAZE HIDROFILA CIRCULAR | C20: Tipo Queijo 91 | D20: 9 fios | E20: 30 | F20: Med Mais | G20: 300gr | H20: =(I20*$I$7)+I20 -> 24.168 | I20: 22.8
A21: 271 | B21: GAZE HIDROFILA CIRCULAR | C21: Tipo Queijo 91 | D21: 11 fios | E21: 25 | F21: Med Mais | G21: 320gr | H21: =(I21*$I$7)+I21 -> 26.3516 | I21: 24.86
A22: 286 | B22: GAZE HIDROFILA CIRCULAR | C22: Tipo Queijo 91 | D22: 13 fios | E22: 25 | F22: Med Mais | G22: 340gr | H22: =(I22*$I$7)+I22 -> 28.4716 | I22: 26.86
A24: COMPRESSA ESTÉRIL
A25: 1 | B25: COMPRESSA ESTÉRIL – 9FIOS | C25: PCT 10 UND | D25: 9 fios | E25: 1000 | F25: Med Mais | H25: =(I25*$I$7)+I25 -> 0.4028 | I25: 0.38
A26: 2 | B26: COMPRESSA ESTÉRIL – 11FIOS | C26: PCT 10 UND | D26: 11 fios | E26: 1000 | F26: Med Mais | H26: =(I26*$I$7)+I26 -> 0.424 | I26: 0.4
A27: 3 | B27: COMPRESSA ESTÉRIL – 13FIOS | C27: PCT 10 UND | D27: 13 fios | E27: 1000 | F27: Med Mais | H27: =(I27*$I$7)+I27 -> 0.4452 | I27: 0.42
A29: CAMPOS OPERATÓRIOS
A30: 1586 | B30: CAMPO OPERATÓRIO - LEVE (Com Radiopaco) | C30: 45X50 PCT C/50 | E30: 12 | F30: Med Mais | G30: 15gr | H30: =(I30*$I$7)+I30 -> 52.47 | I30: 49.5
A31: 1797 | B31: CAMPO OPERATÓRIO - LEVE (Sem Radiopaco) | C31: 45X50 PCT C/50 | E31: 12 | F31: Med Mais | H31: =(I31*$I$7)+I31 -> 51.41 | I31: 48.5
A32: 1588 | B32: CAMPO OPERATÓRIO – Pré encolhido | C32: 25X28 PCT C/5 UND | E32: 150 | F32: Med Mais | H32: =(I32*$I$7)+I32 -> 5.4908 | I32: 5.18
A33: 1587 | B33: CAMPO OPERATÓRIO – Pré encolhido | C33: 25X28 PCT C/2 UND | E33: 300 | F33: Med Mais | H33: =(I33*$I$7)+I33 -> 2.968 | I33: 2.8
A35: ATADURAS - LINHA FARMA
A36: 163 | B36: ATADURA DE CREPE | C36: 10CM x 1,20M | D36: 13 FIOS | E36: 110 DUZIAS | F36: Med Mais | H36: =(I36*$I$7)+I36 -> 4.7276 | I36: 4.46
A37: 480 | B37: ATADURA DE CREPE | C37: 12CM x 1,20M | D37: 13 FIOS | E37: 110 DUZIAS | F37: Med Mais | H37: =(I37*$I$7)+I37 -> 5.8406 | I37: 5.51
A38: 164 | B38: ATADURA DE CREPE | C38: 15CM x 1,20M | D38: 13 FIOS | E38: 90 DUZIAS | F38: Med Mais | H38: =(I38*$I$7)+I38 -> 6.6992 | I38: 6.32
A39: 165 | B39: ATADURA DE CREPE | C39: 20CM x 1,20M | D39: 13 FIOS | E39: 70 DUZIAS | F39: Med Mais | H39: =(I39*$I$7)+I39 -> 8.6284 | I39: 8.14
A40: 166 | B40: ATADURA DE CREPE | C40: 30CM x 1,20M | D40: 13 FIOS | E40: 50 DUZIAS | F40: Med Mais | H40: =(I40*$I$7)+I40 -> 12.7836 | I40: 12.06
A41: 171 | B41: ATADURA DE CREPE | C41: 10CM x 1,80M | D41: 13 FIOS | E41: 100 DUZIAS | F41: Med Mais | H41: =(I41*$I$7)+I41 -> 6.413 | I41: 6.05
A42: 478 | B42: ATADURA DE CREPE | C42: 12CM x 1,80M | D42: 13 FIOS | E42: 90 DUZIAS | F42: Med Mais | H42: =(I42*$I$7)+I42 -> 8.0772 | I42: 7.62
A43: 172 | B43: ATADURA DE CREPE | C43: 15CM x 1,80M | D43: 13 FIOS | E43: 75 DUZIAS | F43: Med Mais | H43: =(I43*$I$7)+I43 -> 9.4446 | I43: 8.91
A44: 173 | B44: ATADURA DE CREPE | C44: 20CM x 1,80M | D44: 13 FIOS | E44: 60 DUZIAS | F44: Med Mais | H44: =(I44*$I$7)+I44 -> 12.2642 | I44: 11.57
A45: 174 | B45: ATADURA DE CREPE | C45: 30CM x 1,80M | D45: 13 FIOS | E45: 40 DUZIAS | F45: Med Mais | H45: =(I45*$I$7)+I45 -> 17.5642 | I45: 16.57
A47: ATADURAS - LINHA HOSPITALAR
A48: 414 | B48: ATADURA DE CREPE | C48: 10CM x 1,20M | D48: 13 FIOS | E48: 110 DUZIAS | F48: Med Mais | H48: =(I48*$I$7)+I48 -> 4.5792 | I48: 4.32
A49: 476 | B49: ATADURA DE CREPE | C49: 12CM x 1,20M | D49: 13 FIOS | E49: 104 DUZIAS | F49: Med Mais | H49: =(I49*$I$7)+I49 -> 5.6604 | I49: 5.34
A50: 419 | B50: ATADURA DE CREPE | C50: 15CM x 1,20M | D50: 13 FIOS | E50: 70 DUZIAS | F50: Med Mais | H50: =(I50*$I$7)+I50 -> 6.519 | I50: 6.15
...

Sheet UltraTextil 3%
A1: TABELA DE PREÇOS - LINHA
A6: COMPRESSAS DE GAZES – PACOTE
A7: CÓD. | B7: PRODUTO | C7: APRESENTAÇÃO | E7: UND CAIXA | F7: MARCA | G7: GRAMAT | H7: PREÇO
A9: 51 | B9: COMPRESSA DE GAZE NÃO ESTERIL | C9: 7,5 X 7,5 - 15x26 (aberta) | D9: 9 fios | E9: 40 | F9: Ultra Têxtil | G9: 500 und | H9: =(I9*$I$7)+I9 -> 14.46 | I9: 14.46
A10: 339 | B10: COMPRESSA DE GAZE NÃO ESTERIL | C10: 7,5 X 7,5 - 15x26 (aberta) | D10: 11 fios | E10: 32 | F10: Ultra Têxtil | G10: 500 und | H10: =(I10*$I$7)+I10 -> 16.58 | I10: 16.58
A11: 349 | B11: COMPRESSA DE GAZE NÃO ESTERIL | C11: 7,5 X 7,5 - 15x26 (aberta) | D11: 13 fios | E11: 32 | F11: Ultra Têxtil | G11: 500 und | H11: =(I11*$I$7)+I11 -> 19.22 | I11: 19.22
A13: COMPRESSAS HIDRÓFILA CIRCULAR – TIPO QUEIJO
A14: 132 | B14: GAZE HIDROFILA CIRCULAR | C14: Tipo Queijo 91 | D14: 9 fios | E14: 20 | F14: Ultra Têxtil | G14: 370gr | H14: =(I14*$I$7)+I14 -> 29.67 | I14: 29.67
A15: 294 | B15: GAZE HIDROFILA CIRCULAR | C15: Tipo Queijo 91 | D15: 11 fios | E15: 20 | F15: Ultra Têxtil | G15: 380gr | H15: =(I15*$I$7)+I15 -> 30.58 | I15: 30.58
A16: 300 | B16: GAZE HIDROFILA CIRCULAR | C16: Tipo Queijo 91 | D16: 13 fios | E16: 20 | F16: Ultra Têxtil | G16: 410gr | H16: =(I16*$I$7)+I16 -> 32.94 | I16: 32.94
A18: COMPRESSA ESTÉRIL
A19: 152 | B19: COMPRESSA ESTÉRIL – 9FIOS | C19: PCT 10 UND | D19: 9 fios | E19: 1000 | F19: Ultra Têxtil | H19: =(I19*$I$7)+I19 -> 0.44 | I19: 0.44
A20: 153 | B20: COMPRESSA ESTÉRIL – 11FIOS | C20: PCT 10 UND | D20: 11 fios | E20: 1000 | F20: Ultra Têxtil | H20: =(I20*$I$7)+I20 -> 0.47 | I20: 0.47
A21: 154 | B21: COMPRESSA ESTÉRIL – 13FIOS | C21: PCT 10 UND | D21: 13 fios | E21: 1000 | F21: Ultra Têxtil | H21: =(I21*$I$7)+I21 -> 0.49 | I21: 0.49
A23: CAMPOS OPERATÓRIOS
A24: 155 | B24: CAMPO OPERATÓRIO - LEVE (Com Radiopaco) | C24: 45X50 PCT C/50 | E24: 12 | F24: Ultra Têxtil | G24: 20gr | H24: =(I24*$I$7)+I24 -> 71 | I24: 71
A25: 158 | B25: CAMPO OPERATÓRIO – Pré encolhido | C25: 25X28 PCT C/5 UND | E25: 150 | F25: Ultra Têxtil | G25: Estéril | H25: =(I25*$I$7)+I25 -> 6.98 | I25: 6.98
A27: Condições de pagamento: 28/35/42
A28: Frete: CIF | F28: Atualizado em 07/01/2026

Sheet UltraTextil 4%
A1: TABELA DE PREÇOS - LINHA
A6: COMPRESSAS DE GAZES – PACOTE
A7: CÓD. | B7: PRODUTO | C7: APRESENTAÇÃO | E7: UND CAIXA | F7: MARCA | G7: GRAMAT | H7: PREÇO | I7: 0.06
A9: 51 | B9: COMPRESSA DE GAZE NÃO ESTERIL | C9: 7,5 X 7,5 - 15x26 (aberta) | D9: 9 fios | E9: 40 | F9: Ultra Têxtil | G9: 500 und | H9: =(I9*$I$7)+I9 -> 15.3276 | I9: 14.46
A10: 339 | B10: COMPRESSA DE GAZE NÃO ESTERIL | C10: 7,5 X 7,5 - 15x26 (aberta) | D10: 11 fios | E10: 32 | F10: Ultra Têxtil | G10: 500 und | H10: =(I10*$I$7)+I10 -> 17.5748 | I10: 16.58
A11: 349 | B11: COMPRESSA DE GAZE NÃO ESTERIL | C11: 7,5 X 7,5 - 15x26 (aberta) | D11: 13 fios | E11: 32 | F11: Ultra Têxtil | G11: 500 und | H11: =(I11*$I$7)+I11 -> 20.3732 | I11: 19.22
A13: COMPRESSAS HIDRÓFILA CIRCULAR – TIPO QUEIJO
A14: 132 | B14: GAZE HIDROFILA CIRCULAR | C14: Tipo Queijo 91 | D14: 9 fios | E14: 20 | F14: Ultra Têxtil | G14: 370gr | H14: =(I14*$I$7)+I14 -> 31.4502 | I14: 29.67
A15: 294 | B15: GAZE HIDROFILA CIRCULAR | C15: Tipo Queijo 91 | D15: 11 fios | E15: 20 | F15: Ultra Têxtil | G15: 380gr | H15: =(I15*$I$7)+I15 -> 32.4148 | I15: 30.58
A16: 300 | B16: GAZE HIDROFILA CIRCULAR | C16: Tipo Queijo 91 | D16: 13 fios | E16: 20 | F16: Ultra Têxtil | G16: 410gr | H16: =(I16*$I$7)+I16 -> 34.9164 | I16: 32.94
A18: COMPRESSA ESTÉRIL
A19: 152 | B19: COMPRESSA ESTÉRIL – 9FIOS | C19: PCT 10 UND | D19: 9 fios | E19: 1000 | F19: Ultra Têxtil | H19: =(I19*$I$7)+I19 -> 0.4664 | I19: 0.44
A20: 153 | B20: COMPRESSA ESTÉRIL – 11FIOS | C20: PCT 10 UND | D20: 11 fios | E20: 1000 | F20: Ultra Têxtil | H20: =(I20*$I$7)+I20 -> 0.4982 | I20: 0.47
A21: 154 | B21: COMPRESSA ESTÉRIL – 13FIOS | C21: PCT 10 UND | D21: 13 fios | E21: 1000 | F21: Ultra Têxtil | H21: =(I21*$I$7)+I21 -> 0.5194 | I21: 0.49
A23: CAMPOS OPERATÓRIOS
A24: 155 | B24: CAMPO OPERATÓRIO - LEVE (Com Radiopaco) | C24: 45X50 PCT C/50 | E24: 12 | F24: Ultra Têxtil | G24: 15gr | H24: =(I24*$I$7)+I24 -> 75.26 | I24: 71
A25: 158 | B25: CAMPO OPERATÓRIO – Pré encolhido | C25: 25X28 PCT C/5 UND | E25: 150 | F25: Ultra Têxtil | G25: Estéril | H25: =(I25*$I$7)+I25 -> 7.3988 | I25: 6.98
A27: Condições de pagamento: 28/35/42
A28: Frete: CIF | F28: Atualizado em 07/01/2026

Sheet MedTextil 3%
A1: TABELA DE PREÇOS - LINHA
A6: COMPRESSAS DE GAZES – PACOTE
A7: CÓD. | B7: PRODUTO | C7: APRESENTAÇÃO | E7: UND CAIXA | F7: MARCA | G7: GRAMAT | H7: PREÇO
A9: 1957 | B9: COMPRESSA DE GAZE NÃO ESTERIL | C9: 7,5 X 7,5 - 15x30 (aberta) | D9: 9 fios | F9: Medtextil | G9: 500 und | H9: =(I9*$I$7)+I9 -> 27.88 | I9: 27.88
A10: 1958 | B10: COMPRESSA DE GAZE NÃO ESTERIL | C10: 7,5 X 7,5 - 15x30 (aberta) | D10: 11 fios | F10: Medtextil | G10: 500 und | H10: =(I10*$I$7)+I10 -> 28.67 | I10: 28.67
A11: 1959 | B11: COMPRESSA DE GAZE NÃO ESTERIL | C11: 7,5 X 7,5 - 15x30 (aberta) | D11: 13 fios | F11: Medtextil | G11: 500 und | H11: =(I11*$I$7)+I11 -> 30.77 | I11: 30.77
A13: COMPRESSAS HIDRÓFILA CIRCULAR – TIPO QUEIJO
A14: 1960 | B14: GAZE HIDROFILA CIRCULAR | C14: Tipo Queijo 91cm x 91m | D14: 9 fios | F14: Medtextil | G14: 1.460gr | H14: =(I14*$I$7)+I14 -> 94.88 | I14: 94.88
A15: 1961 | B15: GAZE HIDROFILA CIRCULAR | C15: Tipo Queijo 91cm x 91m | D15: 11 fios | F15: Medtextil | G15: 1.530gr | H15: =(I15*$I$7)+I15 -> 98.7 | I15: 98.7
A16: 1962 | B16: GAZE HIDROFILA CIRCULAR | C16: Tipo Queijo 91cm x 91m | D16: 13 fios | F16: Medtextil | G16: 1.650gr | H16: =(I16*$I$7)+I16 -> 107.44 | I16: 107.44
A18: COMPRESSA ESTÉRIL
A19: 1641 | B19: COMPRESSA ESTÉRIL – 9FIOS 7,50 X 7,50 | C19: PCT 10 UND | D19: 9 fios | F19: MedTextil | H19: =(I19*$I$7)+I19 -> 0.6 | I19: 0.6
A20: 1642 | B20: COMPRESSA ESTÉRIL – 11FIOS 7,50 X 7,50 | C20: PCT 10 UND | D20: 11 fios | F20: MedTextil | H20: =(I20*$I$7)+I20 -> 0.62 | I20: 0.62
A21: 1643 | B21: COMPRESSA ESTÉRIL – 13FIOS 7,50 X 7,50 | C21: PCT 10 UND | D21: 13 fios | F21: MedTextil | H21: =(I21*$I$7)+I21 -> 0.65 | I21: 0.65
A23: CAMPOS OPERATÓRIOS
A24: 1209 | B24: CAMPO OPERATÓRIO - LEVE | C24: 45X50 PCT C/50 | F24: MedTextil | G24: 25gr | H24: =(I24*$I$7)+I24 -> 86.5 | I24: 86.5
A25: 1640 | B25: CAMPO OPERATÓRIO – Pré encolhido | C25: 25X28 PCT C/5 UND | F25: MedTextil | G25: Estéril | H25: =(I25*$I$7)+I25 -> 7.96 | I25: 7.96
A26: 1639 | B26: CAMPO OPERATÓRIO – Pré encolhido | C26: 25X28 PCT C/2 UND | F26: MedTextil | G26: Estéril | H26: =(I26*$I$7)+I26 -> 4.28 | I26: 4.28
A28: ATADURAS - LINHA FARMA
A29: 159 | B29: ATADURA DE CREPE | C29: 10CM x 1,20M | D29: 13 FIOS | E29: 110 DUZIAS | F29: MedTextil | H29: =(I29*$I$7)+I29 -> 5.21 | I29: 5.21
A30: 481 | B30: ATADURA DE CREPE | C30: 12CM x 1,20M | D30: 13 FIOS | E30: 85 DUZIAS | F30: MedTextil | H30: =(I30*$I$7)+I30 -> 6.44 | I30: 6.44
A31: 160 | B31: ATADURA DE CREPE | C31: 15CM x 1,20M | D31: 13 FIOS | E31: 80 DUZIAS | F31: MedTextil | H31: =(I31*$I$7)+I31 -> 7.38 | I31: 7.38
A32: 161 | B32: ATADURA DE CREPE | C32: 20CM x 1,20M | D32: 13 FIOS | E32: 70 DUZIAS | F32: MedTextil | H32: =(I32*$I$7)+I32 -> 9.49 | I32: 9.49
A33: 162 | B33: ATADURA DE CREPE | C33: 30CM x 1,20M | D33: 13 FIOS | E33: 45 DUZIAS | F33: MedTextil | H33: =(I33*$I$7)+I33 -> 14.13 | I33: 14.13
A34: 167 | B34: ATADURA DE CREPE | C34: 10CM x 1,80M | D34: 13 FIOS | E34: 90 DUZIAS | F34: MedTextil | H34: =(I34*$I$7)+I34 -> 7.19 | I34: 7.19
A35: 479 | B35: ATADURA DE CREPE | C35: 12CM x 1,80M | D35: 13 FIOS | E35: 80 DUZIAS | F35: MedTextil | H35: =(I35*$I$7)+I35 -> 8.9 | I35: 8.9
A36: 168 | B36: ATADURA DE CREPE | C36: 15CM x 1,80M | D36: 13 FIOS | E36: 70 DUZIAS | F36: MedTextil | H36: =(I36*$I$7)+I36 -> 10.52 | I36: 10.52
A37: 169 | B37: ATADURA DE CREPE | C37: 20CM x 1,80M | D37: 13 FIOS | E37: 60 DUZIAS | F37: MedTextil | H37: =(I37*$I$7)+I37 -> 13.51 | I37: 13.51
A38: 170 | B38: ATADURA DE CREPE | C38: 30CM x 1,80M | D38: 13 FIOS | E38: 35 DUZIAS | F38: MedTextil | H38: =(I38*$I$7)+I38 -> 19.48 | I38: 19.48
A40: ATADURAS - LINHA HOSPITALAR
A41: 416 | B41: ATADURA DE CREPE | C41: 10CM x 1,20M | D41: 13 FIOS | E41: 100 DUZIAS | F41: MedTextil | H41: =(I41*$I$7)+I41 -> 5.05 | I41: 5.05
A42: 477 | B42: ATADURA DE CREPE | C42: 12CM x 1,20M | D42: 13 FIOS | E42: 90 DUZIAS | F42: MedTextil | H42: =(I42*$I$7)+I42 -> 6.25 | I42: 6.25
A43: 420 | B43: ATADURA DE CREPE | C43: 15CM x 1,20M | D43: 13 FIOS | E43: 66 DUZIAS | F43: MedTextil | H43: =(I43*$I$7)+I43 -> 7.1 | I43: 7.1
A44: 424 | B44: ATADURA DE CREPE | C44: 20CM x 1,20M | D44: 13 FIOS | E44: 48 DUZIAS | F44: MedTextil | H44: =(I44*$I$7)+I44 -> 9.2 | I44: 9.2
A45: 428 | B45: ATADURA DE CREPE | C45: 30CM x 1,20M | D45: 13 FIOS | E45: 32 DUZIAS | F45: MedTextil | H45: =(I45*$I$7)+I45 -> 13.72 | I45: 13.72
A46: 418 | B46: ATADURA DE CREPE | C46: 10CM x 1,80M | D46: 13 FIOS | E46: 76 DUZIAS | F46: MedTextil | H46: =(I46*$I$7)+I46 -> 7 | I46: 7
A47: 475 | B47: ATADURA DE CREPE | C47: 12CM x 1,80M | D47: 13 FIOS | E47: 60 DUZIAS | F47: MedTextil | H47: =(I47*$I$7)+I47 -> 8.62 | I47: 8.62
A48: 422 | B48: ATADURA DE CREPE | C48: 15CM x 1,80M | D48: 13 FIOS | E48: 48 DUZIAS | F48: MedTextil | H48: =(I48*$I$7)+I48 -> 10.19 | I48: 10.19
A49: 426 | B49: ATADURA DE CREPE | C49: 20CM x 1,80M | D49: 13 FIOS | E49: 38 DUZIAS | F49: MedTextil | H49: =(I49*$I$7)+I49 -> 13.11 | I49: 13.11
A50: 430 | B50: ATADURA DE CREPE | C50: 30CM x 1,80M | D50: 13 FIOS | E50: 26 DUZIAS | F50: MedTextil | H50: =(I50*$I$7)+I50 -> 18.91 | I50: 18.91
...

Sheet MedTextil 4%
A1: TABELA DE PREÇOS - LINHA
A6: COMPRESSAS DE GAZES – PACOTE
A7: CÓD. | B7: PRODUTO | C7: APRESENTAÇÃO | E7: UND CAIXA | F7: MARCA | G7: GRAMAT | H7: PREÇO | I7: 0.06
A9: 1957 | B9: COMPRESSA DE GAZE NÃO ESTERIL | C9: 7,5 X 7,5 - 15x30 (aberta) | D9: 9 fios | E9: 40 | F9: Medtextil | G9: 500 und | H9: =(I9*$I$7)+I9 -> 29.5528 | I9: 27.88
A10: 1958 | B10: COMPRESSA DE GAZE NÃO ESTERIL | C10: 7,5 X 7,5 - 15x30 (aberta) | D10: 11 fios | E10: 32 | F10: Medtextil | G10: 500 und | H10: =(I10*$I$7)+I10 -> 30.3902 | I10: 28.67
A11: 1959 | B11: COMPRESSA DE GAZE NÃO ESTERIL | C11: 7,5 X 7,5 - 15x30 (aberta) | D11: 13 fios | E11: 32 | F11: Medtextil | G11: 500 und | H11: =(I11*$I$7)+I11 -> 32.6162 | I11: 30.77
A13: COMPRESSAS HIDRÓFILA CIRCULAR – TIPO QUEIJO
A14: 1960 | B14: GAZE HIDROFILA CIRCULAR | C14: Tipo Queijo 91cm x 91m | D14: 9 fios | F14: Medtextil | G14: 1.460gr | H14: =(I14*$I$7)+I14 -> 100.5728 | I14: 94.88
A15: 1961 | B15: GAZE HIDROFILA CIRCULAR | C15: Tipo Queijo 91cm x 91m | D15: 11 fios | F15: Medtextil | G15: 1.530gr | H15: =(I15*$I$7)+I15 -> 104.622 | I15: 98.7
A16: 1962 | B16: GAZE HIDROFILA CIRCULAR | C16: Tipo Queijo 91cm x 91m | D16: 13 fios | F16: Medtextil | G16: 1.650gr | H16: =(I16*$I$7)+I16 -> 113.8864 | I16: 107.44
A18: COMPRESSA ESTÉRIL
A19: 1641 | B19: COMPRESSA ESTÉRIL – 9FIOS 7,50 X 7,50 | C19: PCT 10 UND | D19: 9 fios | E19: 1000 | F19: MedTextil | H19: =(I19*$I$7)+I19 -> 0.636 | I19: 0.6
A20: 1642 | B20: COMPRESSA ESTÉRIL – 11FIOS 7,50 X 7,50 | C20: PCT 10 UND | D20: 11 fios | E20: 1000 | F20: MedTextil | H20: =(I20*$I$7)+I20 -> 0.6572 | I20: 0.62
A21: 1643 | B21: COMPRESSA ESTÉRIL – 13FIOS 7,50 X 7,50 | C21: PCT 10 UND | D21: 13 fios | E21: 1000 | F21: MedTextil | H21: =(I21*$I$7)+I21 -> 0.689 | I21: 0.65
A23: CAMPOS OPERATÓRIOS
A24: 1209 | B24: CAMPO OPERATÓRIO - LEVE | C24: 45X50 PCT C/50 | E24: 12 | F24: MedTextil | G24: 15gr | H24: =(I24*$I$7)+I24 -> 91.69 | I24: 86.5
A25: 1640 | B25: CAMPO OPERATÓRIO – Pré encolhido | C25: 25X28 PCT C/5 UND | E25: 150 | F25: MedTextil | G25: Estéril | H25: =(I25*$I$7)+I25 -> 8.4376 | I25: 7.96
A26: 1639 | B26: CAMPO OPERATÓRIO – Pré encolhido | C26: 25X28 PCT C/2 UND | E26: 300 | F26: MedTextil | G26: Estéril | H26: =(I26*$I$7)+I26 -> 4.5368 | I26: 4.28
A28: ATADURAS - LINHA FARMA
A29: 159 | B29: ATADURA DE CREPE | C29: 10CM x 1,20M | D29: 13 FIOS | E29: 110 DUZIAS | F29: MedTextil | H29: =(I29*$I$7)+I29 -> 5.5226 | I29: 5.21
A30: 481 | B30: ATADURA DE CREPE | C30: 12CM x 1,20M | D30: 13 FIOS | E30: 85 DUZIAS | F30: MedTextil | H30: =(I30*$I$7)+I30 -> 6.8264 | I30: 6.44
A31: 160 | B31: ATADURA DE CREPE | C31: 15CM x 1,20M | D31: 13 FIOS | E31: 80 DUZIAS | F31: MedTextil | H31: =(I31*$I$7)+I31 -> 7.8228 | I31: 7.38
A32: 161 | B32: ATADURA DE CREPE | C32: 20CM x 1,20M | D32: 13 FIOS | E32: 70 DUZIAS | F32: MedTextil | H32: =(I32*$I$7)+I32 -> 10.0594 | I32: 9.49
A33: 162 | B33: ATADURA DE CREPE | C33: 30CM x 1,20M | D33: 13 FIOS | E33: 45 DUZIAS | F33: MedTextil | H33: =(I33*$I$7)+I33 -> 14.9778 | I33: 14.13
A34: 167 | B34: ATADURA DE CREPE | C34: 10CM x 1,80M | D34: 13 FIOS | E34: 90 DUZIAS | F34: MedTextil | H34: =(I34*$I$7)+I34 -> 7.6214 | I34: 7.19
A35: 479 | B35: ATADURA DE CREPE | C35: 12CM x 1,80M | D35: 13 FIOS | E35: 80 DUZIAS | F35: MedTextil | H35: =(I35*$I$7)+I35 -> 9.434 | I35: 8.9
A36: 168 | B36: ATADURA DE CREPE | C36: 15CM x 1,80M | D36: 13 FIOS | E36: 70 DUZIAS | F36: MedTextil | H36: =(I36*$I$7)+I36 -> 11.1512 | I36: 10.52
A37: 169 | B37: ATADURA DE CREPE | C37: 20CM x 1,80M | D37: 13 FIOS | E37: 60 DUZIAS | F37: MedTextil | H37: =(I37*$I$7)+I37 -> 14.3206 | I37: 13.51
A38: 170 | B38: ATADURA DE CREPE | C38: 30CM x 1,80M | D38: 13 FIOS | E38: 35 DUZIAS | F38: MedTextil | H38: =(I38*$I$7)+I38 -> 20.6488 | I38: 19.48
A40: ATADURAS - LINHA HOSPITALAR
A41: 416 | B41: ATADURA DE CREPE | C41: 10CM x 1,20M | D41: 13 FIOS | E41: 100 DUZIAS | F41: MedTextil | H41: =(I41*$I$7)+I41 -> 5.353 | I41: 5.05
A42: 477 | B42: ATADURA DE CREPE | C42: 12CM x 1,20M | D42: 13 FIOS | E42: 90 DUZIAS | F42: MedTextil | H42: =(I42*$I$7)+I42 -> 6.625 | I42: 6.25
A43: 420 | B43: ATADURA DE CREPE | C43: 15CM x 1,20M | D43: 13 FIOS | E43: 66 DUZIAS | F43: MedTextil | H43: =(I43*$I$7)+I43 -> 7.526 | I43: 7.1
A44: 424 | B44: ATADURA DE CREPE | C44: 20CM x 1,20M | D44: 13 FIOS | E44: 48 DUZIAS | F44: MedTextil | H44: =(I44*$I$7)+I44 -> 9.752 | I44: 9.2
A45: 428 | B45: ATADURA DE CREPE | C45: 30CM x 1,20M | D45: 13 FIOS | E45: 32 DUZIAS | F45: MedTextil | H45: =(I45*$I$7)+I45 -> 14.5432 | I45: 13.72
A46: 418 | B46: ATADURA DE CREPE | C46: 10CM x 1,80M | D46: 13 FIOS | E46: 76 DUZIAS | F46: MedTextil | H46: =(I46*$I$7)+I46 -> 7.42 | I46: 7
A47: 475 | B47: ATADURA DE CREPE | C47: 12CM x 1,80M | D47: 13 FIOS | E47: 60 DUZIAS | F47: MedTextil | H47: =(I47*$I$7)+I47 -> 9.1372 | I47: 8.62
A48: 422 | B48: ATADURA DE CREPE | C48: 15CM x 1,80M | D48: 13 FIOS | E48: 48 DUZIAS | F48: MedTextil | H48: =(I48*$I$7)+I48 -> 10.8014 | I48: 10.19
A49: 426 | B49: ATADURA DE CREPE | C49: 20CM x 1,80M | D49: 13 FIOS | E49: 38 DUZIAS | F49: MedTextil | H49: =(I49*$I$7)+I49 -> 13.8966 | I49: 13.11
A50: 430 | B50: ATADURA DE CREPE | C50: 30CM x 1,80M | D50: 13 FIOS | E50: 26 DUZIAS | F50: MedTextil | H50: =(I50*$I$7)+I50 -> 20.0446 | I50: 18.91
...
